Workbook
Name TRANSMUTATION_TABLE: 'DO NOT DELETE'!$G$2:$J$42

Sheet INPUT DATA
A1: Input Data Sheet for E-Class Record
C4: REGION | L4: DIVISION
B5: SCHOOL NAME | T5: SCHOOL ID | AD5: SCHOOL YEAR
F7: GRADE & SECTION: | Q7: TEACHER: | AC7: SUBJECT:
B8: LEARNERS' NAMES
B11: MALE
A12: 1 | B12: Quan, Dean D. | C12: 0 | D12: 0 | E12: 0
A13: 2 | B13: Beltran, Julian S. | C13: 0 | D13: 0 | E13: 0
A14: 3 | B14: Castro, Angelo P. | C14: 0 | D14: 0 | E14: 0
A15: 4 | B15: Dela Cruz, Mateo G. | C15: 0 | D15: 0 | E15: 0
A16: 5 | B16: Enriquez, David J. | C16: 0 | D16: 0 | E16: 0
A17: 6 | B17: Fajardo, Simon T. | C17: 0 | D17: 0 | E17: 0
A18: 7 | B18: Garcia, Rafael V. | C18: 0 | D18: 0 | E18: 0
A19: 8 | B19: Hernandez, Luis M. | C19: 0 | D19: 0 | E19: 0
A20: 9 | B20: Ignacio, Kevin R. | C20: 0 | D20: 0 | E20: 0
A21: 10 | B21: Javier, Marcus D. | C21: 0 | D21: 0 | E21: 0
A22: 11 | B22: Lim, Justin B. | C22: 0 | D22: 0 | E22: 0
A23: 12 | B23: Mercado, Nathan F. | C23: 0 | D23: 0 | E23: 0
... A33: 22 | B33: Yabut, Francis K. | C33: 0 | D33: 0 | E33: 0
A34: 23 | C34: 0 | D34: 0 | E34: 0
A35: 24 | C35: 0 | D35: 0 | E35: 0
A36: 25 | C36: 0 | D36: 0 | E36: 0
A37: 26 | C37: 0 | D37: 0 | E37: 0
A38: 27 | C38: 0 | D38: 0 | E38: 0
A39: 28 | C39: 0 | D39: 0 | E39: 0
A40: 29 | C40: 0 | D40: 0 | E40: 0
A41: 30 | C41: 0 | D41: 0 | E41: 0
A42: 31 | C42: 0 | D42: 0 | E42: 0
A43: 32 | C43: 0 | D43: 0 | E43: 0
A44: 33 | C44: 0 | D44: 0 | E44: 0
A45: 34 | C45: 0 | D45: 0 | E45: 0
... A61: 50 | C61: 0 | D61: 0 | E61: 0
B62: FEMALE
A63: 1 | B63: Tokoyami, Towa H. | C63: 0 | D63: 0 | E63: 0
A64: 2 | B64: Piatos, Mary Grace O. | C64: 0 | D64: 0 | E64: 0
A65: 3 | B65: Bautista, Elena M. | C65: 0 | D65: 0 | E65: 0
A66: 4 | B66: Castillo, Isabella D. | C66: 0 | D66: 0 | E66: 0
A67: 5 | B67: Domingo, Chloe A. | C67: 0 | D67: 0 | E67: 0
A68: 6 | B68: Evangelista, Mia K. | C68: 0 | D68: 0 | E68: 0
A69: 7 | B69: Ferrer, Jasmine P. | C69: 0 | D69: 0 | E69: 0
...

Sheet ENGLISH _Q1
A1: Class Record
A3: (Pursuant to Deped Order 8 series of 2015)
C4: REGION | G4: ='INPUT DATA'!G4 -> 0 | L4: DIVISION | O4: ='INPUT DATA'!O4 -> 0
B5: SCHOOL NAME | G5: ='INPUT DATA'!G5 -> 0 | T5: SCHOOL ID | X5: ='INPUT DATA'!X5 -> 0 | AD5: SCHOOL YEAR | AG5: ='INPUT DATA'!AG5 -> 0
A7: FIRST QUARTER | F7: GRADE & SECTION: | K7: ='INPUT DATA'!K7 -> 0 | Q7: TEACHER: | S7: ='INPUT DATA'!S7 -> 0 | AC7: SUBJECT: | AG7: ='INPUT DATA'!AG7 -> 0
B8: LEARNERS' NAMES | F8: WRITTEN WORKS (30%) | S8: PERFORMANCE TASKS (50%) | AF8: QUARTERLY ASSESSMENT (20%) | AI8: Initial | AJ8: Quarterly
F9: 1 | G9: 2 | H9: 3 | I9: 4 | J9: 5 | K9: 6 | L9: 7 | M9: 8 | N9: 9 | O9: 10 | P9: Total | Q9: PS | R9: WS | S9: 1 | T9: 2 | U9: 3 | V9: 4 | W9: 5 | X9: 6 | Y9: 7 | Z9: 8 | AA9: 9 | AB9: 10 | AC9: Total | AD9: PS | AE9: WS | AF9: 1 | AG9: PS | AH9: WS | AI9: Grade | AJ9: Grade
B10: HIGHEST POSSIBLE SCORE | F10: 30 | G10: 50 | H10: 20 | P10: =IF(COUNT($F10:$O10)=0,"",SUM($F10:$O10)) -> 100 | Q10: 100 | R10: 0.3 | S10: 20 | T10: 25 | AC10: =IF(COUNT($S10:$AB10)=0,"",SUM($S10:$AB10)) -> 45 | AD10: 100 | AE10: 0.5 | AF10: 50 | AG10: 100 | AH10: 0.2
B11: MALE
A12: 1 | B12: ='INPUT DATA'!B12 -> Quan, Dean D. | F12: 10 | G12: 25 | H12: 10 | P12: =IF(COUNT($F12:$O12)=0,"",SUM($F12:$O12)) -> 45 | Q12: =IF(ISERROR(IF($P12="","",ROUND(($P12/$P$10)*$Q$10,2))),"",IF($P12="","",ROUND(($P12/$P$10)*$Q$10,2))) -> 45 | R12: =IF($Q12="","",ROUND($Q12*$R$10,2)) -> 13.5 | S12: 19 | T12: 10 | AC12: =IF(COUNT($S12:$AB12)=0,"",SUM($S12:$AB12)) -> 29 | AD12: =IF(ISERROR(IF($AC12="","",ROUND(($AC12/$AC$10)*$AD$10,2))),"",IF($AC12="","",ROUND(($AC12/$AC$10)*$AD$10,2))) -> 64.44 | AE12: =IF($AD12="","",ROUND($AD12*$AE$10,2)) -> 32.22 | AF12: 49 | AG12: =IF(ISERROR(IF($AF12="","",ROUND(($AF12/$AF$10)*$AG$10,2))),"",IF($AF12="","",ROUND(($AF12/$AF$10)*$AG$10,2))) -> 98 | AH12: =IF($AG12="","",ROUND($AG12*$AH$10,2)) -> 19.6 | AI12: =IF(ISERROR(IF($AF12="","",ROUND(SUM($R12,$AE12,$AH12),2))),"",IF($AF12="","",ROUND(SUM($R12,$AE12,$AH12),2))) -> 65.32 | AJ12: =IF(ISERROR(IF($AF12="","",VLOOKUP(AI12,TRANSMUTATION_TABLE,4,TRUE))),"",IF($AF12="","",VLOOKUP(AI12,TRANSMUTATION_TABLE,4,TRUE))) -> 78
A13: 2 | B13: ='INPUT DATA'!B13 -> Beltran, Julian S. | F13: 10 | G13: 25 | H13: 15 | P13: =IF(COUNT($F13:$O13)=0,"",SUM($F13:$O13)) -> 50 | Q13: =IF(ISERROR(IF($P13="","",ROUND(($P13/$P$10)*$Q$10,2))),"",IF($P13="","",ROUND(($P13/$P$10)*$Q$10,2))) -> 50 | R13: =IF($Q13="","",ROUND($Q13*$R$10,2)) -> 15 | S13: 10 | T13: 13 | AC13: =IF(COUNT($S13:$AB13)=0,"",SUM($S13:$AB13)) -> 23 | AD13: =IF(ISERROR(IF($AC13="","",ROUND(($AC13/$AC$10)*$AD$10,2))),"",IF($AC13="","",ROUND(($AC13/$AC$10)*$AD$10,2))) -> 51.11 | AE13: =IF($AD13="","",ROUND($AD13*$AE$10,2)) -> 25.56 | AF13: 48 | AG13: =IF(ISERROR(IF($AF13="","",ROUND(($AF13/$AF$10)*$AG$10,2))),"",IF($AF13="","",ROUND(($AF13/$AF$10)*$AG$10,2))) -> 96 | AH13: =IF($AG13="","",ROUND($AG13*$AH$10,2)) -> 19.2 | AI13: =IF(ISERROR(IF($AF13="","",ROUND(SUM($R13,$AE13,$AH13),2))),"",IF($AF13="","",ROUND(SUM($R13,$AE13,$AH13),2))) -> 59.76 | AJ13: =IF(ISERROR(IF($AF13="","",VLOOKUP(AI13,TRANSMUTATION_TABLE,4,TRUE))),"",IF($AF13="","",VLOOKUP(AI13,TRANSMUTATION_TABLE,4,TRUE))) -> 74
A14: 3 | B14: ='INPUT DATA'!B14 -> Castro, Angelo P. | F14: 13 | G14: 44 | H14: 20 | P14: =IF(COUNT($F14:$O14)=0,"",SUM($F14:$O14)) -> 77 | Q14: =IF(ISERROR(IF($P14="","",ROUND(($P14/$P$10)*$Q$10,2))),"",IF($P14="","",ROUND(($P14/$P$10)*$Q$10,2))) -> 77 | R14: =IF($Q14="","",ROUND($Q14*$R$10,2)) -> 23.1 | S14: 19 | T14: 20 | AC14: =IF(COUNT($S14:$AB14)=0,"",SUM($S14:$AB14)) -> 39 | AD14: =IF(ISERROR(IF($AC14="","",ROUND(($AC14/$AC$10)*$AD$10,2))),"",IF($AC14="","",ROUND(($AC14/$AC$10)*$AD$10,2))) -> 86.67 | AE14: =IF($AD14="","",ROUND($AD14*$AE$10,2)) -> 43.34 | AF14: 38 | AG14: =IF(ISERROR(IF($AF14="","",ROUND(($AF14/$AF$10)*$AG$10,2))),"",IF($AF14="","",ROUND(($AF14/$AF$10)*$AG$10,2))) -> 76 | AH14: =IF($AG14="","",ROUND($AG14*$AH$10,2)) -> 15.2 | AI14: =IF(ISERROR(IF($AF14="","",ROUND(SUM($R14,$AE14,$AH14),2))),"",IF($AF14="","",ROUND(SUM($R14,$AE14,$AH14),2))) -> 81.64 | AJ14: =IF(ISERROR(IF($AF14="","",VLOOKUP(AI14,TRANSMUTATION_TABLE,4,TRUE))),"",IF($AF14="","",VLOOKUP(AI14,TRANSMUTATION_TABLE,4,TRUE))) -> 88
A15: 4 | B15: ='INPUT DATA'!B15 -> Dela Cruz, Mateo G. | F15: 26 | G15: 41 | H15: 19 | P15: =IF(COUNT($F15:$O15)=0,"",SUM($F15:$O15)) -> 86 | Q15: =IF(ISERROR(IF($P15="","",ROUND(($P15/$P$10)*$Q$10,2))),"",IF($P15="","",ROUND(($P15/$P$10)*$Q$10,2))) -> 86 | R15: =IF($Q15="","",ROUND($Q15*$R$10,2)) -> 25.8 | S15: 15 | T15: 19 | AC15: =IF(COUNT($S15:$AB15)=0,"",SUM($S15:$AB15)) -> 34 | AD15: =IF(ISERROR(IF($AC15="","",ROUND(($AC15/$AC$10)*$AD$10,2))),"",IF($AC15="","",ROUND(($AC15/$AC$10)*$AD$10,2))) -> 75.56 | AE15: =IF($AD15="","",ROUND($AD15*$AE$10,2)) -> 37.78 | AF15: 46 | AG15: =IF(ISERROR(IF($AF15="","",ROUND(($AF15/$AF$10)*$AG$10,2))),"",IF($AF15="","",ROUND(($AF15/$AF$10)*$AG$10,2))) -> 92 | AH15: =IF($AG15="","",ROUND($AG15*$AH$10,2)) -> 18.4 | AI15: =IF(ISERROR(IF($AF15="","",ROUND(SUM($R15,$AE15,$AH15),2))),"",IF($AF15="","",ROUND(SUM($R15,$AE15,$AH15),2))) -> 81.98 | AJ15: =IF(ISERROR(IF($AF15="","",VLOOKUP(AI15,TRANSMUTATION_TABLE,4,TRUE))),"",IF($AF15="","",VLOOKUP(AI15,TRANSMUTATION_TABLE,4,TRUE))) -> 88
A16: 5 | B16: ='INPUT DATA'!B16 -> Enriquez, David J. | F16: 22 | G16: 30 | H16: 19 | P16: =IF(COUNT($F16:$O16)=0,"",SUM($F16:$O16)) -> 71 | Q16: =IF(ISERROR(IF($P16="","",ROUND(($P16/$P$10)*$Q$10,2))),"",IF($P16="","",ROUND(($P16/$P$10)*$Q$10,2))) -> 71 | R16: =IF($Q16="","",ROUND($Q16*$R$10,2)) -> 21.3 | S16: 16 | T16: 17 | AC16: =IF(COUNT($S16:$AB16)=0,"",SUM($S16:$AB16)) -> 33 | AD16: =IF(ISERROR(IF($AC16="","",ROUND(($AC16/$AC$10)*$AD$10,2))),"",IF($AC16="","",ROUND(($AC16/$AC$10)*$AD$10,2))) -> 73.33 | AE16: =IF($AD16="","",ROUND($AD16*$AE$10,2)) -> 36.67 | AF16: 45 | AG16: =IF(ISERROR(IF($AF16="","",ROUND(($AF16/$AF$10)*$AG$10,2))),"",IF($AF16="","",ROUND(($AF16/$AF$10)*$AG$10,2))) -> 90 | AH16: =IF($AG16="","",ROUND($AG16*$AH$10,2)) -> 18 | AI16: =IF(ISERROR(IF($AF16="","",ROUND(SUM($R16,$AE16,$AH16),2))),"",IF($AF16="","",ROUND(SUM($R16,$AE16,$AH16),2))) -> 75.97 | AJ16: =IF(ISERROR(IF($AF16="","",VLOOKUP(AI16,TRANSMUTATION_TABLE,4,TRUE))),"",IF($AF16="","",VLOOKUP(AI16,TRANSMUTATION_TABLE,4,TRUE))) -> 84
A17: 6 | B17: ='INPUT DATA'!B17 -> Fajardo, Simon T. | F17: 25 | G17: 25 | H17: 17 | P17: =IF(COUNT($F17:$O17)=0,"",SUM($F17:$O17)) -> 67 | Q17: =IF(ISERROR(IF($P17="","",ROUND(($P17/$P$10)*$Q$10,2))),"",IF($P17="","",ROUND(($P17/$P$10)*$Q$10,2))) -> 67 | R17: =IF($Q17="","",ROUND($Q17*$R$10,2)) -> 20.1 | S17: 18 | T17: 23 | AC17: =IF(COUNT($S17:$AB17)=0,"",SUM($S17:$AB17)) -> 41 | AD17: =IF(ISERROR(IF($AC17="","",ROUND(($AC17/$AC$10)*$AD$10,2))),"",IF($AC17="","",ROUND(($AC17/$AC$10)*$AD$10,2))) -> 91.11 | AE17: =IF($AD17="","",ROUND($AD17*$AE$10,2)) -> 45.56 | AF17: 49 | AG17: =IF(ISERROR(IF($AF17="","",ROUND(($AF17/$AF$10)*$AG$10,2))),"",IF($AF17="","",ROUND(($AF17/$AF$10)*$AG$10,2))) -> 98 | AH17: =IF($AG17="","",ROUND($AG17*$AH$10,2)) -> 19.6 | AI17: =IF(ISERROR(IF($AF17="","",ROUND(SUM($R17,$AE17,$AH17),2))),"",IF($AF17="","",ROUND(SUM($R17,$AE17,$AH17),2))) -> 85.26 | AJ17: =IF(ISERROR(IF($AF17="","",VLOOKUP(AI17,TRANSMUTATION_TABLE,4,TRUE))),"",IF($AF17="","",VLOOKUP(AI17,TRANSMUTATION_TABLE,4,TRUE))) -> 90
A18: 7 | B18: ='INPUT DATA'!B18 -> Garcia, Rafael V. | F18: 29 | G18: 39 | H18: 16 | P18: =IF(COUNT($F18:$O18)=0,"",SUM($F18:$O18)) -> 84 | Q18: =IF(ISERROR(IF($P18="","",ROUND(($P18/$P$10)*$Q$10,2))),"",IF($P18="","",ROUND(($P18/$P$10)*$Q$10,2))) -> 84 | R18: =IF($Q18="","",ROUND($Q18*$R$10,2)) -> 25.2 | S18: 11 | T18: 25 | AC18: =IF(COUNT($S18:$AB18)=0,"",SUM($S18:$AB18)) -> 36 | AD18: =IF(ISERROR(IF($AC18="","",ROUND(($AC18/$AC$10)*$AD$10,2))),"",IF($AC18="","",ROUND(($AC18/$AC$10)*$AD$10,2))) -> 80 | AE18: =IF($AD18="","",ROUND($AD18*$AE$10,2)) -> 40 | AF18: 47 | AG18: =IF(ISERROR(IF($AF18="","",ROUND(($AF18/$AF$10)*$AG$10,2))),"",IF($AF18="","",ROUND(($AF18/$AF$10)*$AG$10,2))) -> 94 | AH18: =IF($AG18="","",ROUND($AG18*$AH$10,2)) -> 18.8 | AI18: =IF(ISERROR(IF($AF18="","",ROUND(SUM($R18,$AE18,$AH18),2))),"",IF($AF18="","",ROUND(SUM($R18,$AE18,$AH18),2))) -> 84 | AJ18: =IF(ISERROR(IF($AF18="","",VLOOKUP(AI18,TRANSMUTATION_TABLE,4,TRUE))),"",IF($AF18="","",VLOOKUP(AI18,TRANSMUTATION_TABLE,4,TRUE))) -> 90
A19: 8 | B19: ='INPUT DATA'!B19 -> Hernandez, Luis M. | D19: 0 | F19: 30 | G19: 40 | H19: 13 | P19: =IF(COUNT($F19:$O19)=0,"",SUM($F19:$O19)) -> 83 | Q19: =IF(ISERROR(IF($P19="","",ROUND(($P19/$P$10)*$Q$10,2))),"",IF($P19="","",ROUND(($P19/$P$10)*$Q$10,2))) -> 83 | R19: =IF($Q19="","",ROUND($Q19*$R$10,2)) -> 24.9 | S19: 17 | T19: 21 | AC19: =IF(COUNT($S19:$AB19)=0,"",SUM($S19:$AB19)) -> 38 | AD19: =IF(ISERROR(IF($AC19="","",ROUND(($AC19/$AC$10)*$AD$10,2))),"",IF($AC19="","",ROUND(($AC19/$AC$10)*$AD$10,2))) -> 84.44 | AE19: =IF($AD19="","",ROUND($AD19*$AE$10,2)) -> 42.22 | AF19: 50 | AG19: =IF(ISERROR(IF($AF19="","",ROUND(($AF19/$AF$10)*$AG$10,2))),"",IF($AF19="","",ROUND(($AF19/$AF$10)*$AG$10,2))) -> 100 | AH19: =IF($AG19="","",ROUND($AG19*$AH$10,2)) -> 20 | AI19: =IF(ISERROR(IF($AF19="","",ROUND(SUM($R19,$AE19,$AH19),2))),"",IF($AF19="","",ROUND(SUM($R19,$AE19,$AH19),2))) -> 87.12 | AJ19: =IF(ISERROR(IF($AF19="","",VLOOKUP(AI19,TRANSMUTATION_TABLE,4,TRUE))),"",IF($AF19="","",VLOOKUP(AI19,TRANSMUTATION_TABLE,4,TRUE))) -> 91
A20: 9 | B20: ='INPUT DATA'!B20 -> Ignacio, Kevin R. | F20: 28 | G20: 49 | H20: 18 | P20: =IF(COUNT($F20:$O20)=0,"",SUM($F20:$O20)) -> 95 | Q20: =IF(ISERROR(IF($P20="","",ROUND(($P20/$P$10)*$Q$10,2))),"",IF($P20="","",ROUND(($P20/$P$10)*$Q$10,2))) -> 95 | R20: =IF($Q20="","",ROUND($Q20*$R$10,2)) -> 28.5 | S20: 19 | T20: 25 | AC20: =IF(COUNT($S20:$AB20)=0,"",SUM($S20:$AB20)) -> 44 | AD20: =IF(ISERROR(IF($AC20="","",ROUND(($AC20/$AC$10)*$AD$10,2))),"",IF($AC20="","",ROUND(($AC20/$AC$10)*$AD$10,2))) -> 97.78 | AE20: =IF($AD20="","",ROUND($AD20*$AE$10,2)) -> 48.89 | AF20: 46 | AG20: =IF(ISERROR(IF($AF20="","",ROUND(($AF20/$AF$10)*$AG$10,2))),"",IF($AF20="","",ROUND(($AF20/$AF$10)*$AG$10,2))) -> 92 | AH20: =IF($AG20="","",ROUND($AG20*$AH$10,2)) -> 18.4 | AI20: =IF(ISERROR(IF($AF20="","",ROUND(SUM($R20,$AE20,$AH20),2))),"",IF($AF20="","",ROUND(SUM($R20,$AE20,$AH20),2))) -> 95.79 | AJ20: =IF(ISERROR(IF($AF20="","",VLOOKUP(AI20,TRANSMUTATION_TABLE,4,TRUE))),"",IF($AF20="","",VLOOKUP(AI20,TRANSMUTATION_TABLE,4,TRUE))) -> 97
A21: 10 | B21: ='INPUT DATA'!B21 -> Javier, Marcus D. | F21: 30 | G21: 48 | H21: 11 | P21: =IF(COUNT($F21:$O21)=0,"",SUM($F21:$O21)) -> 89 | Q21: =IF(ISERROR(IF($P21="","",ROUND(($P21/$P$10)*$Q$10,2))),"",IF($P21="","",ROUND(($P21/$P$10)*$Q$10,2))) -> 89 | R21: =IF($Q21="","",ROUND($Q21*$R$10,2)) -> 26.7 | S21: 13 | T21: 20 | AC21: =IF(COUNT($S21:$AB21)=0,"",SUM($S21:$AB21)) -> 33 | AD21: =IF(ISERROR(IF($AC21="","",ROUND(($AC21/$AC$10)*$AD$10,2))),"",IF($AC21="","",ROUND(($AC21/$AC$10)*$AD$10,2))) -> 73.33 | AE21: =IF($AD21="","",ROUND($AD21*$AE$10,2)) -> 36.67 | AF21: 49 | AG21: =IF(ISERROR(IF($AF21="","",ROUND(($AF21/$AF$10)*$AG$10,2))),"",IF($AF21="","",ROUND(($AF21/$AF$10)*$AG$10,2))) -> 98 | AH21: =IF($AG21="","",ROUND($AG21*$AH$10,2)) -> 19.6 | AI21: =IF(ISERROR(IF($AF21="","",ROUND(SUM($R21,$AE21,$AH21),2))),"",IF($AF21="","",ROUND(SUM($R21,$AE21,$AH21),2))) -> 82.97 | AJ21: =IF(ISERROR(IF($AF21="","",VLOOKUP(AI21,TRANSMUTATION_TABLE,4,TRUE))),"",IF($AF21="","",VLOOKUP(AI21,TRANSMUTATION_TABLE,4,TRUE))) -> 89
A22: 11 | B22: ='INPUT DATA'!B22 -> Lim, Justin B. | D22: 0 | F22: 28 | G22: 47 | H22: 19 | P22: =IF(COUNT($F22:$O22)=0,"",SUM($F22:$O22)) -> 94 | Q22: =IF(ISERROR(IF($P22="","",ROUND(($P22/$P$10)*$Q$10,2))),"",IF($P22="","",ROUND(($P22/$P$10)*$Q$10,2))) -> 94 | R22: =IF($Q22="","",ROUND($Q22*$R$10,2)) -> 28.2 | S22: 13 | T22: 18 | AC22: =IF(COUNT($S22:$AB22)=0,"",SUM($S22:$AB22)) -> 31 | AD22: =IF(ISERROR(IF($AC22="","",ROUND(($AC22/$AC$10)*$AD$10,2))),"",IF($AC22="","",ROUND(($AC22/$AC$10)*$AD$10,2))) -> 68.89 | AE22: =IF($AD22="","",ROUND($AD22*$AE$10,2)) -> 34.45 | AF22: 49 | AG22: =IF(ISERROR(IF($AF22="","",ROUND(($AF22/$AF$10)*$AG$10,2))),"",IF($AF22="","",ROUND(($AF22/$AF$10)*$AG$10,2))) -> 98 | AH22: =IF($AG22="","",ROUND($AG22*$AH$10,2)) -> 19.6 | AI22: =IF(ISERROR(IF($AF22="","",ROUND(SUM($R22,$AE22,$AH22),2))),"",IF($AF22="","",ROUND(SUM($R22,$AE22,$AH22),2))) -> 82.25 | AJ22: =IF(ISERROR(IF($AF22="","",VLOOKUP(AI22,TRANSMUTATION_TABLE,4,TRUE))),"",IF($AF22="","",VLOOKUP(AI22,TRANSMUTATION_TABLE,4,TRUE))) -> 88
A23: 12 | B23: ='INPUT DATA'!B23 -> Mercado, Nathan F. | F23: 25 | G23: 50 | H23: 20 | P23: =IF(COUNT($F23:$O23)=0,"",SUM($F23:$O23)) -> 95 | Q23: =IF(ISERROR(IF($P23="","",ROUND(($P23/$P$10)*$Q$10,2))),"",IF($P23="","",ROUND(($P23/$P$10)*$Q$10,2))) -> 95 | R23: =IF($Q23="","",ROUND($Q23*$R$10,2)) -> 28.5 | S23: 15 | T23: 16 | AC23: =IF(COUNT($S23:$AB23)=0,"",SUM($S23:$AB23)) -> 31 | AD23: =IF(ISERROR(IF($AC23="","",ROUND(($AC23/$AC$10)*$AD$10,2))),"",IF($AC23="","",ROUND(($AC23/$AC$10)*$AD$10,2))) -> 68.89 | AE23: =IF($AD23="","",ROUND($AD23*$AE$10,2)) -> 34.45 | AF23: 50 | AG23: =IF(ISERROR(IF($AF23="","",ROUND(($AF23/$AF$10)*$AG$10,2))),"",IF($AF23="","",ROUND(($AF23/$AF$10)*$AG$10,2))) -> 100 | AH23: =IF($AG23="","",ROUND($AG23*$AH$10,2)) -> 20 | AI23: =IF(ISERROR(IF($AF23="","",ROUND(SUM($R23,$AE23,$AH23),2))),"",IF($AF23="","",ROUND(SUM($R23,$AE23,$AH23),2))) -> 82.95 | AJ23: =IF(ISERROR(IF($AF23="","",VLOOKUP(AI23,TRANSMUTATION_TABLE,4,TRUE))),"",IF($AF23="","",VLOOKUP(AI23,TRANSMUTATION_TABLE,4,TRUE))) -> 89
A24: 13 | B24: ='INPUT DATA'!B24 -> Naval, Patrick S. | F24: 29 | G24: 38 | H24: 15 | P24: =IF(COUNT($F24:$O24)=0,"",SUM($F24:$O24)) -> 82 | Q24: =IF(ISERROR(IF($P24="","",ROUND(($P24/$P$10)*$Q$10,2))),"",IF($P24="","",ROUND(($P24/$P$10)*$Q$10,2))) -> 82 | R24: =IF($Q24="","",ROUND($Q24*$R$10,2)) -> 24.6 | S24: 17 | T24: 20 | AC24: =IF(COUNT($S24:$AB24)=0,"",SUM($S24:$AB24)) -> 37 | AD24: =IF(ISERROR(IF($AC24="","",ROUND(($AC24/$AC$10)*$AD$10,2))),"",IF($AC24="","",ROUND(($AC24/$AC$10)*$AD$10,2))) -> 82.22 | AE24: =IF($AD24="","",ROUND($AD24*$AE$10,2)) -> 41.11 | AF24: 40 | AG24: =IF(ISERROR(IF($AF24="","",ROUND(($AF24/$AF$10)*$AG$10,2))),"",IF($AF24="","",ROUND(($AF24/$AF$10)*$AG$10,2))) -> 80 | AH24: =IF($AG24="","",ROUND($AG24*$AH$10,2)) -> 16 | AI24: =IF(ISERROR(IF($AF24="","",ROUND(SUM($R24,$AE24,$AH24),2))),"",IF($AF24="","",ROUND(SUM($R24,$AE24,$AH24),2))) -> 81.71 | AJ24: =IF(ISERROR(IF($AF24="","",VLOOKUP(AI24,TRANSMUTATION_TABLE,4,TRUE))),"",IF($AF24="","",VLOOKUP(AI24,TRANSMUTATION_TABLE,4,TRUE))) -> 88
A25: 14 | B25: ='INPUT DATA'!B25 -> Ocampo, Gabriel C. | F25: 28 | G25: 47 | H25: 19 | P25: =IF(COUNT($F25:$O25)=0,"",SUM($F25:$O25)) -> 94 | Q25: =IF(ISERROR(IF($P25="","",ROUND(($P25/$P$10)*$Q$10,2))),"",IF($P25="","",ROUND(($P25/$P$10)*$Q$10,2))) -> 94 | R25: =IF($Q25="","",ROUND($Q25*$R$10,2)) -> 28.2 | S25: 18 | T25: 17 | AC25: =IF(COUNT($S25:$AB25)=0,"",SUM($S25:$AB25)) -> 35 | AD25: =IF(ISERROR(IF($AC25="","",ROUND(($AC25/$AC$10)*$AD$10,2))),"",IF($AC25="","",ROUND(($AC25/$AC$10)*$AD$10,2))) -> 77.78 | AE25: =IF($AD25="","",ROUND($AD25*$AE$10,2)) -> 38.89 | AF25: 49 | AG25: =IF(ISERROR(IF($AF25="","",ROUND(($AF25/$AF$10)*$AG$10,2))),"",IF($AF25="","",ROUND(($AF25/$AF$10)*$AG$10,2))) -> 98 | AH25: =IF($AG25="","",ROUND($AG25*$AH$10,2)) -> 19.6 | AI25: =IF(ISERROR(IF($AF25="","",ROUND(SUM($R25,$AE25,$AH25),2))),"",IF($AF25="","",ROUND(SUM($R25,$AE25,$AH25),2))) -> 86.69 | AJ25: =IF(ISERROR(IF($AF25="","",VLOOKUP(AI25,TRANSMUTATION_TABLE,4,TRUE))),"",IF($AF25="","",VLOOKUP(AI25,TRANSMUTATION_TABLE,4,TRUE))) -> 91
A26: 15 | B26: ='INPUT DATA'!B26 -> Pascual, Cedric A. | F26: 30 | G26: 15 | H26: 13 | P26: =IF(COUNT($F26:$O26)=0,"",SUM($F26:$O26)) -> 58 | Q26: =IF(ISERROR(IF($P26="","",ROUND(($P26/$P$10)*$Q$10,2))),"",IF($P26="","",ROUND(($P26/$P$10)*$Q$10,2))) -> 58 | R26: =IF($Q26="","",ROUND($Q26*$R$10,2)) -> 17.4 | S26: 13 | T26: 20 | AC26: =IF(COUNT($S26:$AB26)=0,"",SUM($S26:$AB26)) -> 33 | AD26: =IF(ISERROR(IF($AC26="","",ROUND(($AC26/$AC$10)*$AD$10,2))),"",IF($AC26="","",ROUND(($AC26/$AC$10)*$AD$10,2))) -> 73.33 | AE26: =IF($AD26="","",ROUND($AD26*$AE$10,2)) -> 36.67 | AF26: 50 | AG26: =IF(ISERROR(IF($AF26="","",ROUND(($AF26/$AF$10)*$AG$10,2))),"",IF($AF26="","",ROUND(($AF26/$AF$10)*$AG$10,2))) -> 100 | AH26: =IF($AG26="","",ROUND($AG26*$AH$10,2)) -> 20 | AI26: =IF(ISERROR(IF($AF26="","",ROUND(SUM($R26,$AE26,$AH26),2))),"",IF($AF26="","",ROUND(SUM($R26,$AE26,$AH26),2))) -> 74.07 | AJ26: =IF(ISERROR(IF($AF26="","",VLOOKUP(AI26,TRANSMUTATION_TABLE,4,TRUE))),"",IF($AF26="","",VLOOKUP(AI26,TRANSMUTATION_TABLE,4,TRUE))) -> 83
A27: 16 | B27: ='INPUT DATA'!B27 -> Quizon, Timothy E. | F27: 19 | G27: 50 | H27: 12 | P27: =IF(COUNT($F27:$O27)=0,"",SUM($F27:$O27)) -> 81 | Q27: =IF(ISERROR(IF($P27="","",ROUND(($P27/$P$10)*$Q$10,2))),"",IF($P27="","",ROUND(($P27/$P$10)*$Q$10,2))) -> 81 | R27: =IF($Q27="","",ROUND($Q27*$R$10,2)) -> 24.3 | S27: 16 | T27: 19 | AC27: =IF(COUNT($S27:$AB27)=0,"",SUM($S27:$AB27)) -> 35 | AD27: =IF(ISERROR(IF($AC27="","",ROUND(($AC27/$AC$10)*$AD$10,2))),"",IF($AC27="","",ROUND(($AC27/$AC$10)*$AD$10,2))) -> 77.78 | AE27: =IF($AD27="","",ROUND($AD27*$AE$10,2)) -> 38.89 | AF27: 49 | AG27: =IF(ISERROR(IF($AF27="","",ROUND(($AF27/$AF$10)*$AG$10,2))),"",IF($AF27="","",ROUND(($AF27/$AF$10)*$AG$10,2))) -> 98 | AH27: =IF($AG27="","",ROUND($AG27*$AH$10,2)) -> 19.6 | AI27: =IF(ISERROR(IF($AF27="","",ROUND(SUM($R27,$AE27,$AH27),2))),"",IF($AF27="","",ROUND(SUM($R27,$AE27,$AH27),2))) -> 82.79 | AJ27: =IF(ISERROR(IF($AF27="","",VLOOKUP(AI27,TRANSMUTATION_TABLE,4,TRUE))),"",IF($AF27="","",VLOOKUP(AI27,TRANSMUTATION_TABLE,4,TRUE))) -> 89
A28: 17 | B28: ='INPUT DATA'!B28 -> Reyes, Dominic L. | F28: 20 | G28: 48 | H28: 19 | P28: =IF(COUNT($F28:$O28)=0,"",SUM($F28:$O28)) -> 87 | Q28: =IF(ISERROR(IF($P28="","",ROUND(($P28/$P$10)*$Q$10,2))),"",IF($P28="","",ROUND(($P28/$P$10)*$Q$10,2))) -> 87 | R28: =IF($Q28="","",ROUND($Q28*$R$10,2)) -> 26.1 | S28: 19 | T28: 16 | AC28: =IF(COUNT($S28:$AB28)=0,"",SUM($S28:$AB28)) -> 35 | AD28: =IF(ISERROR(IF($AC28="","",ROUND(($AC28/$AC$10)*$AD$10,2))),"",IF($AC28="","",ROUND(($AC28/$AC$10)*$AD$10,2))) -> 77.78 | AE28: =IF($AD28="","",ROUND($AD28*$AE$10,2)) -> 38.89 | AF28: 47 | AG28: =IF(ISERROR(IF($AF28="","",ROUND(($AF28/$AF$10)*$AG$10,2))),"",IF($AF28="","",ROUND(($AF28/$AF$10)*$AG$10,2))) -> 94 | AH28: =IF($AG28="","",ROUND($AG28*$AH$10,2)) -> 18.8 | AI28: =IF(ISERROR(IF($AF28="","",ROUND(SUM($R28,$AE28,$AH28),2))),"",IF($AF28="","",ROUND(SUM($R28,$AE28,$AH28),2))) -> 83.79 | AJ28: =IF(ISERROR(IF($AF28="","",VLOOKUP(AI28,TRANSMUTATION_TABLE,4,TRUE))),"",IF($AF28="","",VLOOKUP(AI28,TRANSMUTATION_TABLE,4,TRUE))) -> 89
A29: 18 | B29: ='INPUT DATA'!B29 -> Santos, Elijah J. | F29: 27 | G29: 45 | H29: 17 | P29: =IF(COUNT($F29:$O29)=0,"",SUM($F29:$O29)) -> 89 | Q29: =IF(ISERROR(IF($P29="","",ROUND(($P29/$P$10)*$Q$10,2))),"",IF($P29="","",ROUND(($P29/$P$10)*$Q$10,2))) -> 89 | R29: =IF($Q29="","",ROUND($Q29*$R$10,2)) -> 26.7 | S29: 13 | T29: 18 | AC29: =IF(COUNT($S29:$AB29)=0,"",SUM($S29:$AB29)) -> 31 | AD29: =IF(ISERROR(IF($AC29="","",ROUND(($AC29/$AC$10)*$AD$10,2))),"",IF($AC29="","",ROUND(($AC29/$AC$10)*$AD$10,2))) -> 68.89 | AE29: =IF($AD29="","",ROUND($AD29*$AE$10,2)) -> 34.45 | AF29: 50 | AG29: =IF(ISERROR(IF($AF29="","",ROUND(($AF29/$AF$10)*$AG$10,2))),"",IF($AF29="","",ROUND(($AF29/$AF$10)*$AG$10,2))) -> 100 | AH29: =IF($AG29="","",ROUND($AG29*$AH$10,2)) -> 20 | AI29: =IF(ISERROR(IF($AF29="","",ROUND(SUM($R29,$AE29,$AH29),2))),"",IF($AF29="","",ROUND(SUM($R29,$AE29,$AH29),2))) -> 81.15 | AJ29: =IF(ISERROR(IF($AF29="","",VLOOKUP(AI29,TRANSMUTATION_TABLE,4,TRUE))),"",IF($AF29="","",VLOOKUP(AI29,TRANSMUTATION_TABLE,4,TRUE))) -> 88
A30: 19 | B30: ='INPUT DATA'!B30 -> Torres, Benedict M. | F30: 29 | G30: 40 | H30: 14 | P30: =IF(COUNT($F30:$O30)=0,"",SUM($F30:$O30)) -> 83 | Q30: =IF(ISERROR(IF($P30="","",ROUND(($P30/$P$10)*$Q$10,2))),"",IF($P30="","",ROUND(($P30/$P$10)*$Q$10,2))) -> 83 | R30: =IF($Q30="","",ROUND($Q30*$R$10,2)) -> 24.9 | S30: 20 | T30: 19 | AC30: =IF(COUNT($S30:$AB30)=0,"",SUM($S30:$AB30)) -> 39 | AD30: =IF(ISERROR(IF($AC30="","",ROUND(($AC30/$AC$10)*$AD$10,2))),"",IF($AC30="","",ROUND(($AC30/$AC$10)*$AD$10,2))) -> 86.67 | AE30: =IF($AD30="","",ROUND($AD30*$AE$10,2)) -> 43.34 | AF30: 47 | AG30: =IF(ISERROR(IF($AF30="","",ROUND(($AF30/$AF$10)*$AG$10,2))),"",IF($AF30="","",ROUND(($AF30/$AF$10)*$AG$10,2))) -> 94 | AH30: =IF($AG30="","",ROUND($AG30*$AH$10,2)) -> 18.8 | AI30: =IF(ISERROR(IF($AF30="","",ROUND(SUM($R30,$AE30,$AH30),2))),"",IF($AF30="","",ROUND(SUM($R30,$AE30,$AH30),2))) -> 87.04 | AJ30: =IF(ISERROR(IF($AF30="","",VLOOKUP(AI30,TRANSMUTATION_TABLE,4,TRUE))),"",IF($AF30="","",VLOOKUP(AI30,TRANSMUTATION_TABLE,4,TRUE))) -> 91
A31: 20 | B31: ='INPUT DATA'!B31 -> Umali, Vincent P. | F31: 30 | G31: 39 | H31: 20 | P31: =IF(COUNT($F31:$O31)=0,"",SUM($F31:$O31)) -> 89 | Q31: =IF(ISERROR(IF($P31="","",ROUND(($P31/$P$10)*$Q$10,2))),"",IF($P31="","",ROUND(($P31/$P$10)*$Q$10,2))) -> 89 | R31: =IF($Q31="","",ROUND($Q31*$R$10,2)) -> 26.7 | S31: 17 | T31: 20 | AC31: =IF(COUNT($S31:$AB31)=0,"",SUM($S31:$AB31)) -> 37 | AD31: =IF(ISERROR(IF($AC31="","",ROUND(($AC31/$AC$10)*$AD$10,2))),"",IF($AC31="","",ROUND(($AC31/$AC$10)*$AD$10,2))) -> 82.22 | AE31: =IF($AD31="","",ROUND($AD31*$AE$10,2)) -> 41.11 | AF31: 50 | AG31: =IF(ISERROR(IF($AF31="","",ROUND(($AF31/$AF$10)*$AG$10,2))),"",IF($AF31="","",ROUND(($AF31/$AF$10)*$AG$10,2))) -> 100 | AH31: =IF($AG31="","",ROUND($AG31*$AH$10,2)) -> 20 | AI31: =IF(ISERROR(IF($AF31="","",ROUND(SUM($R31,$AE31,$AH31),2))),"",IF($AF31="","",ROUND(SUM($R31,$AE31,$AH31),2))) -> 87.81 | AJ31: =IF(ISERROR(IF($AF31="","",VLOOKUP(AI31,TRANSMUTATION_TABLE,4,TRUE))),"",IF($AF31="","",VLOOKUP(AI31,TRANSMUTATION_TABLE,4,TRUE))) -> 92
A32: 21 | B32: ='INPUT DATA'!B32 -> Valdez, Christian R. | F32: 27 | G32: 48 | H32: 18 | P32: =IF(COUNT($F32:$O32)=0,"",SUM($F32:$O32)) -> 93 | Q32: =IF(ISERROR(IF($P32="","",ROUND(($P32/$P$10)*$Q$10,2))),"",IF($P32="","",ROUND(($P32/$P$10)*$Q$10,2))) -> 93 | R32: =IF($Q32="","",ROUND($Q32*$R$10,2)) -> 27.9 | S32: 10 | T32: 20 | AC32: =IF(COUNT($S32:$AB32)=0,"",SUM($S32:$AB32)) -> 30 | AD32: =IF(ISERROR(IF($AC32="","",ROUND(($AC32/$AC$10)*$AD$10,2))),"",IF($AC32="","",ROUND(($AC32/$AC$10)*$AD$10,2))) -> 66.67 | AE32: =IF($AD32="","",ROUND($AD32*$AE$10,2)) -> 33.34 | AF32: 49 | AG32: =IF(ISERROR(IF($AF32="","",ROUND(($AF32/$AF$10)*$AG$10,2))),"",IF($AF32="","",ROUND(($AF32/$AF$10)*$AG$10,2))) -> 98 | AH32: =IF($AG32="","",ROUND($AG32*$AH$10,2)) -> 19.6 | AI32: =IF(ISERROR(IF($AF32="","",ROUND(SUM($R32,$AE32,$AH32),2))),"",IF($AF32="","",ROUND(SUM($R32,$AE32,$AH32),2))) -> 80.84 | AJ32: =IF(ISERROR(IF($AF32="","",VLOOKUP(AI32,TRANSMUTATION_TABLE,4,TRUE))),"",IF($AF32="","",VLOOKUP(AI32,TRANSMUTATION_TABLE,4,TRUE))) -> 88
A33: 22 | B33: ='INPUT DATA'!B33 -> Yabut, Francis K. | F33: 25 | G33: 50 | H33: 20 | P33: =IF(COUNT($F33:$O33)=0,"",SUM($F33:$O33)) -> 95 | Q33: =IF(ISERROR(IF($P33="","",ROUND(($P33/$P$10)*$Q$10,2))),"",IF($P33="","",ROUND(($P33/$P$10)*$Q$10,2))) -> 95 | R33: =IF($Q33="","",ROUND($Q33*$R$10,2)) -> 28.5 | S33: 13 | T33: 18 | AC33: =IF(COUNT($S33:$AB33)=0,"",SUM($S33:$AB33)) -> 31 | AD33: =IF(ISERROR(IF($AC33="","",ROUND(($AC33/$AC$10)*$AD$10,2))),"",IF($AC33="","",ROUND(($AC33/$AC$10)*$AD$10,2))) -> 68.89 | AE33: =IF($AD33="","",ROUND($AD33*$AE$10,2)) -> 34.45 | AF33: 48 | AG33: =IF(ISERROR(IF($AF33="","",ROUND(($AF33/$AF$10)*$AG$10,2))),"",IF($AF33="","",ROUND(($AF33/$AF$10)*$AG$10,2))) -> 96 | AH33: =IF($AG33="","",ROUND($AG33*$AH$10,2)) -> 19.2 | AI33: =IF(ISERROR(IF($AF33="","",ROUND(SUM($R33,$AE33,$AH33),2))),"",IF($AF33="","",ROUND(SUM($R33,$AE33,$AH33),2))) -> 82.15 | AJ33: =IF(ISERROR(IF($AF33="","",VLOOKUP(AI33,TRANSMUTATION_TABLE,4,TRUE))),"",IF($AF33="","",VLOOKUP(AI33,TRANSMUTATION_TABLE,4,TRUE))) -> 88
A34: 23 | B34: ='INPUT DATA'!B34 -> 0 | P34: =IF(COUNT($F34:$O34)=0,"",SUM($F34:$O34)) | Q34: =IF(ISERROR(IF($P34="","",ROUND(($P34/$P$10)*$Q$10,2))),"",IF($P34="","",ROUND(($P34/$P$10)*$Q$10,2))) | R34: =IF($Q34="","",ROUND($Q34*$R$10,2)) | AC34: =IF(COUNT($S34:$AB34)=0,"",SUM($S34:$AB34)) | AD34: =IF(ISERROR(IF($AC34="","",ROUND(($AC34/$AC$10)*$AD$10,2))),"",IF($AC34="","",ROUND(($AC34/$AC$10)*$AD$10,2))) | AE34: =IF($AD34="","",ROUND($AD34*$AE$10,2)) | AG34: =IF(ISERROR(IF($AF34="","",ROUND(($AF34/$AF$10)*$AG$10,2))),"",IF($AF34="","",ROUND(($AF34/$AF$10)*$AG$10,2))) | AH34: =IF($AG34="","",ROUND($AG34*$AH$10,2)) | AI34: =IF(ISERROR(IF($AF34="","",ROUND(SUM($R34,$AE34,$AH34),2))),"",IF($AF34="","",ROUND(SUM($R34,$AE34,$AH34),2))) | AJ34: =IF(ISERROR(IF($AF34="","",VLOOKUP(AI34,TRANSMUTATION_TABLE,4,TRUE))),"",IF($AF34="","",VLOOKUP(AI34,TRANSMUTATION_TABLE,4,TRUE)))
A35: 24 | B35: ='INPUT DATA'!B35 -> 0 | P35: =IF(COUNT($F35:$O35)=0,"",SUM($F35:$O35)) | Q35: =IF(ISERROR(IF($P35="","",ROUND(($P35/$P$10)*$Q$10,2))),"",IF($P35="","",ROUND(($P35/$P$10)*$Q$10,2))) | R35: =IF($Q35="","",ROUND($Q35*$R$10,2)) | AC35: =IF(COUNT($S35:$AB35)=0,"",SUM($S35:$AB35)) | AD35: =IF(ISERROR(IF($AC35="","",ROUND(($AC35/$AC$10)*$AD$10,2))),"",IF($AC35="","",ROUND(($AC35/$AC$10)*$AD$10,2))) | AE35: =IF($AD35="","",ROUND($AD35*$AE$10,2)) | AG35: =IF(ISERROR(IF($AF35="","",ROUND(($AF35/$AF$10)*$AG$10,2))),"",IF($AF35="","",ROUND(($AF35/$AF$10)*$AG$10,2))) | AH35: =IF($AG35="","",ROUND($AG35*$AH$10,2)) | AI35: =IF(ISERROR(IF($AF35="","",ROUND(SUM($R35,$AE35,$AH35),2))),"",IF($AF35="","",ROUND(SUM($R35,$AE35,$AH35),2))) | AJ35: =IF(ISERROR(IF($AF35="","",VLOOKUP(AI35,TRANSMUTATION_TABLE,4,TRUE))),"",IF($AF35="","",VLOOKUP(AI35,TRANSMUTATION_TABLE,4,TRUE)))
A36: 25 | B36: ='INPUT DATA'!B36 -> 0 | P36: =IF(COUNT($F36:$O36)=0,"",SUM($F36:$O36)) | Q36: =IF(ISERROR(IF($P36="","",ROUND(($P36/$P$10)*$Q$10,2))),"",IF($P36="","",ROUND(($P36/$P$10)*$Q$10,2))) | R36: =IF($Q36="","",ROUND($Q36*$R$10,2)) | AC36: =IF(COUNT($S36:$AB36)=0,"",SUM($S36:$AB36)) | AD36: =IF(ISERROR(IF($AC36="","",ROUND(($AC36/$AC$10)*$AD$10,2))),"",IF($AC36="","",ROUND(($AC36/$AC$10)*$AD$10,2))) | AE36: =IF($AD36="","",ROUND($AD36*$AE$10,2)) | AG36: =IF(ISERROR(IF($AF36="","",ROUND(($AF36/$AF$10)*$AG$10,2))),"",IF($AF36="","",ROUND(($AF36/$AF$10)*$AG$10,2))) | AH36: =IF($AG36="","",ROUND($AG36*$AH$10,2)) | AI36: =IF(ISERROR(IF($AF36="","",ROUND(SUM($R36,$AE36,$AH36),2))),"",IF($AF36="","",ROUND(SUM($R36,$AE36,$AH36),2))) | AJ36: =IF(ISERROR(IF($AF36="","",VLOOKUP(AI36,TRANSMUTATION_TABLE,4,TRUE))),"",IF($AF36="","",VLOOKUP(AI36,TRANSMUTATION_TABLE,4,TRUE)))
A37: 26 | B37: ='INPUT DATA'!B37 -> 0 | P37: =IF(COUNT($F37:$O37)=0,"",SUM($F37:$O37)) | Q37: =IF(ISERROR(IF($P37="","",ROUND(($P37/$P$10)*$Q$10,2))),"",IF($P37="","",ROUND(($P37/$P$10)*$Q$10,2))) | R37: =IF($Q37="","",ROUND($Q37*$R$10,2)) | AC37: =IF(COUNT($S37:$AB37)=0,"",SUM($S37:$AB37)) | AD37: =IF(ISERROR(IF($AC37="","",ROUND(($AC37/$AC$10)*$AD$10,2))),"",IF($AC37="","",ROUND(($AC37/$AC$10)*$AD$10,2))) | AE37: =IF($AD37="","",ROUND($AD37*$AE$10,2)) | AG37: =IF(ISERROR(IF($AF37="","",ROUND(($AF37/$AF$10)*$AG$10,2))),"",IF($AF37="","",ROUND(($AF37/$AF$10)*$AG$10,2))) | AH37: =IF($AG37="","",ROUND($AG37*$AH$10,2)) | AI37: =IF(ISERROR(IF($AF37="","",ROUND(SUM($R37,$AE37,$AH37),2))),"",IF($AF37="","",ROUND(SUM($R37,$AE37,$AH37),2))) | AJ37: =IF(ISERROR(IF($AF37="","",VLOOKUP(AI37,TRANSMUTATION_TABLE,4,TRUE))),"",IF($AF37="","",VLOOKUP(AI37,TRANSMUTATION_TABLE,4,TRUE)))
A38: 27 | B38: ='INPUT DATA'!B38 -> 0 | P38: =IF(COUNT($F38:$O38)=0,"",SUM($F38:$O38)) | Q38: =IF(ISERROR(IF($P38="","",ROUND(($P38/$P$10)*$Q$10,2))),"",IF($P38="","",ROUND(($P38/$P$10)*$Q$10,2))) | R38: =IF($Q38="","",ROUND($Q38*$R$10,2)) | AC38: =IF(COUNT($S38:$AB38)=0,"",SUM($S38:$AB38)) | AD38: =IF(ISERROR(IF($AC38="","",ROUND(($AC38/$AC$10)*$AD$10,2))),"",IF($AC38="","",ROUND(($AC38/$AC$10)*$AD$10,2))) | AE38: =IF($AD38="","",ROUND($AD38*$AE$10,2)) | AG38: =IF(ISERROR(IF($AF38="","",ROUND(($AF38/$AF$10)*$AG$10,2))),"",IF($AF38="","",ROUND(($AF38/$AF$10)*$AG$10,2))) | AH38: =IF($AG38="","",ROUND($AG38*$AH$10,2)) | AI38: =IF(ISERROR(IF($AF38="","",ROUND(SUM($R38,$AE38,$AH38),2))),"",IF($AF38="","",ROUND(SUM($R38,$AE38,$AH38),2))) | AJ38: =IF(ISERROR(IF($AF38="","",VLOOKUP(AI38,TRANSMUTATION_TABLE,4,TRUE))),"",IF($AF38="","",VLOOKUP(AI38,TRANSMUTATION_TABLE,4,TRUE)))
A39: 28 | B39: ='INPUT DATA'!B39 -> 0 | P39: =IF(COUNT($F39:$O39)=0,"",SUM($F39:$O39)) | Q39: =IF(ISERROR(IF($P39="","",ROUND(($P39/$P$10)*$Q$10,2))),"",IF($P39="","",ROUND(($P39/$P$10)*$Q$10,2))) | R39: =IF($Q39="","",ROUND($Q39*$R$10,2)) | AC39: =IF(COUNT($S39:$AB39)=0,"",SUM($S39:$AB39)) | AD39: =IF(ISERROR(IF($AC39="","",ROUND(($AC39/$AC$10)*$AD$10,2))),"",IF($AC39="","",ROUND(($AC39/$AC$10)*$AD$10,2))) | AE39: =IF($AD39="","",ROUND($AD39*$AE$10,2)) | AG39: =IF(ISERROR(IF($AF39="","",ROUND(($AF39/$AF$10)*$AG$10,2))),"",IF($AF39="","",ROUND(($AF39/$AF$10)*$AG$10,2))) | AH39: =IF($AG39="","",ROUND($AG39*$AH$10,2)) | AI39: =IF(ISERROR(IF($AF39="","",ROUND(SUM($R39,$AE39,$AH39),2))),"",IF($AF39="","",ROUND(SUM($R39,$AE39,$AH39),2))) | AJ39: =IF(ISERROR(IF($AF39="","",VLOOKUP(AI39,TRANSMUTATION_TABLE,4,TRUE))),"",IF($AF39="","",VLOOKUP(AI39,TRANSMUTATION_TABLE,4,TRUE)))
A40: 29 | B40: ='INPUT DATA'!B40 -> 0 | P40: =IF(COUNT($F40:$O40)=0,"",SUM($F40:$O40)) | Q40: =IF(ISERROR(IF($P40="","",ROUND(($P40/$P$10)*$Q$10,2))),"",IF($P40="","",ROUND(($P40/$P$10)*$Q$10,2))) | R40: =IF($Q40="","",ROUND($Q40*$R$10,2)) | AC40: =IF(COUNT($S40:$AB40)=0,"",SUM($S40:$AB40)) | AD40: =IF(ISERROR(IF($AC40="","",ROUND(($AC40/$AC$10)*$AD$10,2))),"",IF($AC40="","",ROUND(($AC40/$AC$10)*$AD$10,2))) | AE40: =IF($AD40="","",ROUND($AD40*$AE$10,2)) | AG40: =IF(ISERROR(IF($AF40="","",ROUND(($AF40/$AF$10)*$AG$10,2))),"",IF($AF40="","",ROUND(($AF40/$AF$10)*$AG$10,2))) | AH40: =IF($AG40="","",ROUND($AG40*$AH$10,2)) | AI40: =IF(ISERROR(IF($AF40="","",ROUND(SUM($R40,$AE40,$AH40),2))),"",IF($AF40="","",ROUND(SUM($R40,$AE40,$AH40),2))) | AJ40: =IF(ISERROR(IF($AF40="","",VLOOKUP(AI40,TRANSMUTATION_TABLE,4,TRUE))),"",IF($AF40="","",VLOOKUP(AI40,TRANSMUTATION_TABLE,4,TRUE)))
A41: 30 | B41: ='INPUT DATA'!B41 -> 0 | P41: =IF(COUNT($F41:$O41)=0,"",SUM($F41:$O41)) | Q41: =IF(ISERROR(IF($P41="","",ROUND(($P41/$P$10)*$Q$10,2))),"",IF($P41="","",ROUND(($P41/$P$10)*$Q$10,2))) | R41: =IF($Q41="","",ROUND($Q41*$R$10,2)) | AC41: =IF(COUNT($S41:$AB41)=0,"",SUM($S41:$AB41)) | AD41: =IF(ISERROR(IF($AC41="","",ROUND(($AC41/$AC$10)*$AD$10,2))),"",IF($AC41="","",ROUND(($AC41/$AC$10)*$AD$10,2))) | AE41: =IF($AD41="","",ROUND($AD41*$AE$10,2)) | AG41: =IF(ISERROR(IF($AF41="","",ROUND(($AF41/$AF$10)*$AG$10,2))),"",IF($AF41="","",ROUND(($AF41/$AF$10)*$AG$10,2))) | AH41: =IF($AG41="","",ROUND($AG41*$AH$10,2)) | AI41: =IF(ISERROR(IF($AF41="","",ROUND(SUM($R41,$AE41,$AH41),2))),"",IF($AF41="","",ROUND(SUM($R41,$AE41,$AH41),2))) | AJ41: =IF(ISERROR(IF($AF41="","",VLOOKUP(AI41,TRANSMUTATION_TABLE,4,TRUE))),"",IF($AF41="","",VLOOKUP(AI41,TRANSMUTATION_TABLE,4,TRUE)))
A42: 31 | B42: ='INPUT DATA'!B42 -> 0 | P42: =IF(COUNT($F42:$O42)=0,"",SUM($F42:$O42)) | Q42: =IF(ISERROR(IF($P42="","",ROUND(($P42/$P$10)*$Q$10,2))),"",IF($P42="","",ROUND(($P42/$P$10)*$Q$10,2))) | R42: =IF($Q42="","",ROUND($Q42*$R$10,2)) | AC42: =IF(COUNT($S42:$AB42)=0,"",SUM($S42:$AB42)) | AD42: =IF(ISERROR(IF($AC42="","",ROUND(($AC42/$AC$10)*$AD$10,2))),"",IF($AC42="","",ROUND(($AC42/$AC$10)*$AD$10,2))) | AE42: =IF($AD42="","",ROUND($AD42*$AE$10,2)) | AG42: =IF(ISERROR(IF($AF42="","",ROUND(($AF42/$AF$10)*$AG$10,2))),"",IF($AF42="","",ROUND(($AF42/$AF$10)*$AG$10,2))) | AH42: =IF($AG42="","",ROUND($AG42*$AH$10,2)) | AI42: =IF(ISERROR(IF($AF42="","",ROUND(SUM($R42,$AE42,$AH42),2))),"",IF($AF42="","",ROUND(SUM($R42,$AE42,$AH42),2))) | AJ42: =IF(ISERROR(IF($AF42="","",VLOOKUP(AI42,TRANSMUTATION_TABLE,4,TRUE))),"",IF($AF42="","",VLOOKUP(AI42,TRANSMUTATION_TABLE,4,TRUE)))
...

Sheet ENGLISH _Q2
A1: Class Record
A3: (Pursuant to Deped Order 8 series of 2015)
C4: REGION | G4: ='INPUT DATA'!G4 -> 0 | L4: DIVISION | O4: ='INPUT DATA'!O4 -> 0
B5: SCHOOL NAME | G5: ='INPUT DATA'!G5 -> 0 | T5: SCHOOL ID | X5: ='INPUT DATA'!X5 -> 0 | AD5: SCHOOL YEAR | AG5: ='INPUT DATA'!AG5 -> 0
A7: SECOND QUARTER | F7: GRADE & SECTION: | K7: ='INPUT DATA'!K7 -> 0 | Q7: TEACHER: | S7: ='INPUT DATA'!S7 -> 0 | AC7: SUBJECT: | AG7: ='INPUT DATA'!AG7 -> 0
B8: LEARNERS' NAMES | F8: WRITTEN WORKS (30%) | S8: PERFORMANCE TASKS (50%) | AF8: QUARTERLY ASSESSMENT (20%) | AI8: Initial | AJ8: Quarterly
F9: 1 | G9: 2 | H9: 3 | I9: 4 | J9: 5 | K9: 6 | L9: 7 | M9: 8 | N9: 9 | O9: 10 | P9: Total | Q9: PS | R9: WS | S9: 1 | T9: 2 | U9: 3 | V9: 4 | W9: 5 | X9: 6 | Y9: 7 | Z9: 8 | AA9: 9 | AB9: 10 | AC9: Total | AD9: PS | AE9: WS | AF9: 1 | AG9: PS | AH9: WS | AI9: Grade | AJ9: Grade
B10: HIGHEST POSSIBLE SCORE | F10: 30 | G10: 50 | H10: 20 | P10: =IF(COUNT($F10:$O10)=0,"",SUM($F10:$O10)) -> 100 | Q10: 100 | R10: 0.3 | S10: 25 | AC10: =IF(COUNT($S10:$AB10)=0,"",SUM($S10:$AB10)) -> 25 | AD10: 100 | AE10: 0.5 | AF10: 50 | AG10: 100 | AH10: 0.2
B11: MALE
A12: 1 | B12: ='INPUT DATA'!B12 -> Quan, Dean D. | F12: 30 | G12: 50 | H12: 20 | P12: =IF(COUNT($F12:$O12)=0,"",SUM($F12:$O12)) -> 100 | Q12: =IF(ISERROR(IF($P12="","",ROUND(($P12/$P$10)*$Q$10,2))),"",IF($P12="","",ROUND(($P12/$P$10)*$Q$10,2))) -> 100 | R12: =IF($Q12="","",ROUND($Q12*$R$10,2)) -> 30 | S12: 25 | AC12: =IF(COUNT($S12:$AB12)=0,"",SUM($S12:$AB12)) -> 25 | AD12: =IF(ISERROR(IF($AC12="","",ROUND(($AC12/$AC$10)*$AD$10,2))),"",IF($AC12="","",ROUND(($AC12/$AC$10)*$AD$10,2))) -> 100 | AE12: =IF($AD12="","",ROUND($AD12*$AE$10,2)) -> 50 | AF12: 47 | AG12: =IF(ISERROR(IF($AF12="","",ROUND(($AF12/$AF$10)*$AG$10,2))),"",IF($AF12="","",ROUND(($AF12/$AF$10)*$AG$10,2))) -> 94 | AH12: =IF($AG12="","",ROUND($AG12*$AH$10,2)) -> 18.8 | AI12: =IF(ISERROR(IF($AF12="","",ROUND(SUM($R12,$AE12,$AH12),2))),"",IF($AF12="","",ROUND(SUM($R12,$AE12,$AH12),2))) -> 98.8 | AJ12: =IF(ISERROR(IF($AF12="","",VLOOKUP(AI12,TRANSMUTATION_TABLE,4,TRUE))),"",IF($AF12="","",VLOOKUP(AI12,TRANSMUTATION_TABLE,4,TRUE))) -> 99
A13: 2 | B13: ='INPUT DATA'!B13 -> Beltran, Julian S. | F13: 29 | G13: 45 | H13: 19 | P13: =IF(COUNT($F13:$O13)=0,"",SUM($F13:$O13)) -> 93 | Q13: =IF(ISERROR(IF($P13="","",ROUND(($P13/$P$10)*$Q$10,2))),"",IF($P13="","",ROUND(($P13/$P$10)*$Q$10,2))) -> 93 | R13: =IF($Q13="","",ROUND($Q13*$R$10,2)) -> 27.9 | S13: 20 | AC13: =IF(COUNT($S13:$AB13)=0,"",SUM($S13:$AB13)) -> 20 | AD13: =IF(ISERROR(IF($AC13="","",ROUND(($AC13/$AC$10)*$AD$10,2))),"",IF($AC13="","",ROUND(($AC13/$AC$10)*$AD$10,2))) -> 80 | AE13: =IF($AD13="","",ROUND($AD13*$AE$10,2)) -> 40 | AF13: 45 | AG13: =IF(ISERROR(IF($AF13="","",ROUND(($AF13/$AF$10)*$AG$10,2))),"",IF($AF13="","",ROUND(($AF13/$AF$10)*$AG$10,2))) -> 90 | AH13: =IF($AG13="","",ROUND($AG13*$AH$10,2)) -> 18 | AI13: =IF(ISERROR(IF($AF13="","",ROUND(SUM($R13,$AE13,$AH13),2))),"",IF($AF13="","",ROUND(SUM($R13,$AE13,$AH13),2))) -> 85.9 | AJ13: =IF(ISERROR(IF($AF13="","",VLOOKUP(AI13,TRANSMUTATION_TABLE,4,TRUE))),"",IF($AF13="","",VLOOKUP(AI13,TRANSMUTATION_TABLE,4,TRUE))) -> 91
A14: 3 | B14: ='INPUT DATA'!B14 -> Castro, Angelo P. | F14: 25 | G14: 49 | H14: 13 | P14: =IF(COUNT($F14:$O14)=0,"",SUM($F14:$O14)) -> 87 | Q14: =IF(ISERROR(IF($P14="","",ROUND(($P14/$P$10)*$Q$10,2))),"",IF($P14="","",ROUND(($P14/$P$10)*$Q$10,2))) -> 87 | R14: =IF($Q14="","",ROUND($Q14*$R$10,2)) -> 26.1 | S14: 24 | AC14: =IF(COUNT($S14:$AB14)=0,"",SUM($S14:$AB14)) -> 24 | AD14: =IF(ISERROR(IF($AC14="","",ROUND(($AC14/$AC$10)*$AD$10,2))),"",IF($AC14="","",ROUND(($AC14/$AC$10)*$AD$10,2))) -> 96 | AE14: =IF($AD14="","",ROUND($AD14*$AE$10,2)) -> 48 | AF14: 49 | AG14: =IF(ISERROR(IF($AF14="","",ROUND(($AF14/$AF$10)*$AG$10,2))),"",IF($AF14="","",ROUND(($AF14/$AF$10)*$AG$10,2))) -> 98 | AH14: =IF($AG14="","",ROUND($AG14*$AH$10,2)) -> 19.6 | AI14: =IF(ISERROR(IF($AF14="","",ROUND(SUM($R14,$AE14,$AH14),2))),"",IF($AF14="","",ROUND(SUM($R14,$AE14,$AH14),2))) -> 93.7 | AJ14: =IF(ISERROR(IF($AF14="","",VLOOKUP(AI14,TRANSMUTATION_TABLE,4,TRUE))),"",IF($AF14="","",VLOOKUP(AI14,TRANSMUTATION_TABLE,4,TRUE))) -> 96
A15: 4 | B15: ='INPUT DATA'!B15 -> Dela Cruz, Mateo G. | F15: 30 | G15: 40 | H15: 15 | P15: =IF(COUNT($F15:$O15)=0,"",SUM($F15:$O15)) -> 85 | Q15: =IF(ISERROR(IF($P15="","",ROUND(($P15/$P$10)*$Q$10,2))),"",IF($P15="","",ROUND(($P15/$P$10)*$Q$10,2))) -> 85 | R15: =IF($Q15="","",ROUND($Q15*$R$10,2)) -> 25.5 | S15: 20 | AC15: =IF(COUNT($S15:$AB15)=0,"",SUM($S15:$AB15)) -> 20 | AD15: =IF(ISERROR(IF($AC15="","",ROUND(($AC15/$AC$10)*$AD$10,2))),"",IF($AC15="","",ROUND(($AC15/$AC$10)*$AD$10,2))) -> 80 | AE15: =IF($AD15="","",ROUND($AD15*$AE$10,2)) -> 40 | AF15: 47 | AG15: =IF(ISERROR(IF($AF15="","",ROUND(($AF15/$AF$10)*$AG$10,2))),"",IF($AF15="","",ROUND(($AF15/$AF$10)*$AG$10,2))) -> 94 | AH15: =IF($AG15="","",ROUND($AG15*$AH$10,2)) -> 18.8 | AI15: =IF(ISERROR(IF($AF15="","",ROUND(SUM($R15,$AE15,$AH15),2))),"",IF($AF15="","",ROUND(SUM($R15,$AE15,$AH15),2))) -> 84.3 | AJ15: =IF(ISERROR(IF($AF15="","",VLOOKUP(AI15,TRANSMUTATION_TABLE,4,TRUE))),"",IF($AF15="","",VLOOKUP(AI15,TRANSMUTATION_TABLE,4,TRUE))) -> 90
A16: 5 | B16: ='INPUT DATA'!B16 -> Enriquez, David J. | F16: 28 | G16: 50 | H16: 19 | P16: =IF(COUNT($F16:$O16)=0,"",SUM($F16:$O16)) -> 97 | Q16: =IF(ISERROR(IF($P16="","",ROUND(($P16/$P$10)*$Q$10,2))),"",IF($P16="","",ROUND(($P16/$P$10)*$Q$10,2))) -> 97 | R16: =IF($Q16="","",ROUND($Q16*$R$10,2)) -> 29.1 | S16: 21 | AC16: =IF(COUNT($S16:$AB16)=0,"",SUM($S16:$AB16)) -> 21 | AD16: =IF(ISERROR(IF($AC16="","",ROUND(($AC16/$AC$10)*$AD$10,2))),"",IF($AC16="","",ROUND(($AC16/$AC$10)*$AD$10,2))) -> 84 | AE16: =IF($AD16="","",ROUND($AD16*$AE$10,2)) -> 42 | AF16: 50 | AG16: =IF(ISERROR(IF($AF16="","",ROUND(($AF16/$AF$10)*$AG$10,2))),"",IF($AF16="","",ROUND(($AF16/$AF$10)*$AG$10,2))) -> 100 | AH16: =IF($AG16="","",ROUND($AG16*$AH$10,2)) -> 20 | AI16: =IF(ISERROR(IF($AF16="","",ROUND(SUM($R16,$AE16,$AH16),2))),"",IF($AF16="","",ROUND(SUM($R16,$AE16,$AH16),2))) -> 91.1 | AJ16: =IF(ISERROR(IF($AF16="","",VLOOKUP(AI16,TRANSMUTATION_TABLE,4,TRUE))),"",IF($AF16="","",VLOOKUP(AI16,TRANSMUTATION_TABLE,4,TRUE))) -> 94
A17: 6 | B17: ='INPUT DATA'!B17 -> Fajardo, Simon T. | F17: 28 | G17: 48 | H17: 15 | P17: =IF(COUNT($F17:$O17)=0,"",SUM($F17:$O17)) -> 91 | Q17: =IF(ISERROR(IF($P17="","",ROUND(($P17/$P$10)*$Q$10,2))),"",IF($P17="","",ROUND(($P17/$P$10)*$Q$10,2))) -> 91 | R17: =IF($Q17="","",ROUND($Q17*$R$10,2)) -> 27.3 | S17: 22 | AC17: =IF(COUNT($S17:$AB17)=0,"",SUM($S17:$AB17)) -> 22 | AD17: =IF(ISERROR(IF($AC17="","",ROUND(($AC17/$AC$10)*$AD$10,2))),"",IF($AC17="","",ROUND(($AC17/$AC$10)*$AD$10,2))) -> 88 | AE17: =IF($AD17="","",ROUND($AD17*$AE$10,2)) -> 44 | AF17: 49 | AG17: =IF(ISERROR(IF($AF17="","",ROUND(($AF17/$AF$10)*$AG$10,2))),"",IF($AF17="","",ROUND(($AF17/$AF$10)*$AG$10,2))) -> 98 | AH17: =IF($AG17="","",ROUND($AG17*$AH$10,2)) -> 19.6 | AI17: =IF(ISERROR(IF($AF17="","",ROUND(SUM($R17,$AE17,$AH17),2))),"",IF($AF17="","",ROUND(SUM($R17,$AE17,$AH17),2))) -> 90.9 | AJ17: =IF(ISERROR(IF($AF17="","",VLOOKUP(AI17,TRANSMUTATION_TABLE,4,TRUE))),"",IF($AF17="","",VLOOKUP(AI17,TRANSMUTATION_TABLE,4,TRUE))) -> 94
A18: 7 | B18: ='INPUT DATA'!B18 -> Garcia, Rafael V. | F18: 29 | G18: 49 | H18: 19 | P18: =IF(COUNT($F18:$O18)=0,"",SUM($F18:$O18)) -> 97 | Q18: =IF(ISERROR(IF($P18="","",ROUND(($P18/$P$10)*$Q$10,2))),"",IF($P18="","",ROUND(($P18/$P$10)*$Q$10,2))) -> 97 | R18: =IF($Q18="","",ROUND($Q18*$R$10,2)) -> 29.1 | S18: 25 | AC18: =IF(COUNT($S18:$AB18)=0,"",SUM($S18:$AB18)) -> 25 | AD18: =IF(ISERROR(IF($AC18="","",ROUND(($AC18/$AC$10)*$AD$10,2))),"",IF($AC18="","",ROUND(($AC18/$AC$10)*$AD$10,2))) -> 100 | AE18: =IF($AD18="","",ROUND($AD18*$AE$10,2)) -> 50 | AF18: 45 | AG18: =IF(ISERROR(IF($AF18="","",ROUND(($AF18/$AF$10)*$AG$10,2))),"",IF($AF18="","",ROUND(($AF18/$AF$10)*$AG$10,2))) -> 90 | AH18: =IF($AG18="","",ROUND($AG18*$AH$10,2)) -> 18 | AI18: =IF(ISERROR(IF($AF18="","",ROUND(SUM($R18,$AE18,$AH18),2))),"",IF($AF18="","",ROUND(SUM($R18,$AE18,$AH18),2))) -> 97.1 | AJ18: =IF(ISERROR(IF($AF18="","",VLOOKUP(AI18,TRANSMUTATION_TABLE,4,TRUE))),"",IF($AF18="","",VLOOKUP(AI18,TRANSMUTATION_TABLE,4,TRUE))) -> 98
A19: 8 | B19: ='INPUT DATA'!B19 -> Hernandez, Luis M. | D19: 0 | F19: 28 | G19: 45 | H19: 20 | P19: =IF(COUNT($F19:$O19)=0,"",SUM($F19:$O19)) -> 93 | Q19: =IF(ISERROR(IF($P19="","",ROUND(($P19/$P$10)*$Q$10,2))),"",IF($P19="","",ROUND(($P19/$P$10)*$Q$10,2))) -> 93 | R19: =IF($Q19="","",ROUND($Q19*$R$10,2)) -> 27.9 | S19: 21 | AC19: =IF(COUNT($S19:$AB19)=0,"",SUM($S19:$AB19)) -> 21 | AD19: =IF(ISERROR(IF($AC19="","",ROUND(($AC19/$AC$10)*$AD$10,2))),"",IF($AC19="","",ROUND(($AC19/$AC$10)*$AD$10,2))) -> 84 | AE19: =IF($AD19="","",ROUND($AD19*$AE$10,2)) -> 42 | AF19: 50 | AG19: =IF(ISERROR(IF($AF19="","",ROUND(($AF19/$AF$10)*$AG$10,2))),"",IF($AF19="","",ROUND(($AF19/$AF$10)*$AG$10,2))) -> 100 | AH19: =IF($AG19="","",ROUND($AG19*$AH$10,2)) -> 20 | AI19: =IF(ISERROR(IF($AF19="","",ROUND(SUM($R19,$AE19,$AH19),2))),"",IF($AF19="","",ROUND(SUM($R19,$AE19,$AH19),2))) -> 89.9 | AJ19: =IF(ISERROR(IF($AF19="","",VLOOKUP(AI19,TRANSMUTATION_TABLE,4,TRUE))),"",IF($AF19="","",VLOOKUP(AI19,TRANSMUTATION_TABLE,4,TRUE))) -> 93
A20: 9 | B20: ='INPUT DATA'!B20 -> Ignacio, Kevin R. | F20: 25 | G20: 40 | H20: 15 | P20: =IF(COUNT($F20:$O20)=0,"",SUM($F20:$O20)) -> 80 | Q20: =IF(ISERROR(IF($P20="","",ROUND(($P20/$P$10)*$Q$10,2))),"",IF($P20="","",ROUND(($P20/$P$10)*$Q$10,2))) -> 80 | R20: =IF($Q20="","",ROUND($Q20*$R$10,2)) -> 24 | S20: 24 | AC20: =IF(COUNT($S20:$AB20)=0,"",SUM($S20:$AB20)) -> 24 | AD20: =IF(ISERROR(IF($AC20="","",ROUND(($AC20/$AC$10)*$AD$10,2))),"",IF($AC20="","",ROUND(($AC20/$AC$10)*$AD$10,2))) -> 96 | AE20: =IF($AD20="","",ROUND($AD20*$AE$10,2)) -> 48 | AF20: 45 | AG20: =IF(ISERROR(IF($AF20="","",ROUND(($AF20/$AF$10)*$AG$10,2))),"",IF($AF20="","",ROUND(($AF20/$AF$10)*$AG$10,2))) -> 90 | AH20: =IF($AG20="","",ROUND($AG20*$AH$10,2)) -> 18 | AI20: =IF(ISERROR(IF($AF20="","",ROUND(SUM($R20,$AE20,$AH20),2))),"",IF($AF20="","",ROUND(SUM($R20,$AE20,$AH20),2))) -> 90 | AJ20: =IF(ISERROR(IF($AF20="","",VLOOKUP(AI20,TRANSMUTATION_TABLE,4,TRUE))),"",IF($AF20="","",VLOOKUP(AI20,TRANSMUTATION_TABLE,4,TRUE))) -> 93
A21: 10 | B21: ='INPUT DATA'!B21 -> Javier, Marcus D. | F21: 25 | G21: 50 | H21: 19 | P21: =IF(COUNT($F21:$O21)=0,"",SUM($F21:$O21)) -> 94 | Q21: =IF(ISERROR(IF($P21="","",ROUND(($P21/$P$10)*$Q$10,2))),"",IF($P21="","",ROUND(($P21/$P$10)*$Q$10,2))) -> 94 | R21: =IF($Q21="","",ROUND($Q21*$R$10,2)) -> 28.2 | S21: 20 | AC21: =IF(COUNT($S21:$AB21)=0,"",SUM($S21:$AB21)) -> 20 | AD21: =IF(ISERROR(IF($AC21="","",ROUND(($AC21/$AC$10)*$AD$10,2))),"",IF($AC21="","",ROUND(($AC21/$AC$10)*$AD$10,2))) -> 80 | AE21: =IF($AD21="","",ROUND($AD21*$AE$10,2)) -> 40 | AF21: 50 | AG21: =IF(ISERROR(IF($AF21="","",ROUND(($AF21/$AF$10)*$AG$10,2))),"",IF($AF21="","",ROUND(($AF21/$AF$10)*$AG$10,2))) -> 100 | AH21: =IF($AG21="","",ROUND($AG21*$AH$10,2)) -> 20 | AI21: =IF(ISERROR(IF($AF21="","",ROUND(SUM($R21,$AE21,$AH21),2))),"",IF($AF21="","",ROUND(SUM($R21,$AE21,$AH21),2))) -> 88.2 | AJ21: =IF(ISERROR(IF($AF21="","",VLOOKUP(AI21,TRANSMUTATION_TABLE,4,TRUE))),"",IF($AF21="","",VLOOKUP(AI21,TRANSMUTATION_TABLE,4,TRUE))) -> 92
A22: 11 | B22: ='INPUT DATA'!B22 -> Lim, Justin B. | D22: 0 | F22: 28 | G22: 48 | H22: 18 | P22: =IF(COUNT($F22:$O22)=0,"",SUM($F22:$O22)) -> 94 | Q22: =IF(ISERROR(IF($P22="","",ROUND(($P22/$P$10)*$Q$10,2))),"",IF($P22="","",ROUND(($P22/$P$10)*$Q$10,2))) -> 94 | R22: =IF($Q22="","",ROUND($Q22*$R$10,2)) -> 28.2 | S22: 21 | AC22: =IF(COUNT($S22:$AB22)=0,"",SUM($S22:$AB22)) -> 21 | AD22: =IF(ISERROR(IF($AC22="","",ROUND(($AC22/$AC$10)*$AD$10,2))),"",IF($AC22="","",ROUND(($AC22/$AC$10)*$AD$10,2))) -> 84 | AE22: =IF($AD22="","",ROUND($AD22*$AE$10,2)) -> 42 | AF22: 47 | AG22: =IF(ISERROR(IF($AF22="","",ROUND(($AF22/$AF$10)*$AG$10,2))),"",IF($AF22="","",ROUND(($AF22/$AF$10)*$AG$10,2))) -> 94 | AH22: =IF($AG22="","",ROUND($AG22*$AH$10,2)) -> 18.8 | AI22: =IF(ISERROR(IF($AF22="","",ROUND(SUM($R22,$AE22,$AH22),2))),"",IF($AF22="","",ROUND(SUM($R22,$AE22,$AH22),2))) -> 89 | AJ22: =IF(ISERROR(IF($AF22="","",VLOOKUP(AI22,TRANSMUTATION_TABLE,4,TRUE))),"",IF($AF22="","",VLOOKUP(AI22,TRANSMUTATION_TABLE,4,TRUE))) -> 93
A23: 12 | B23: ='INPUT DATA'!B23 -> Mercado, Nathan F. | F23: 29 | G23: 49 | H23: 15 | P23: =IF(COUNT($F23:$O23)=0,"",SUM($F23:$O23)) -> 93 | Q23: =IF(ISERROR(IF($P23="","",ROUND(($P23/$P$10)*$Q$10,2))),"",IF($P23="","",ROUND(($P23/$P$10)*$Q$10,2))) -> 93 | R23: =IF($Q23="","",ROUND($Q23*$R$10,2)) -> 27.9 | S23: 22 | AC23: =IF(COUNT($S23:$AB23)=0,"",SUM($S23:$AB23)) -> 22 | AD23: =IF(ISERROR(IF($AC23="","",ROUND(($AC23/$AC$10)*$AD$10,2))),"",IF($AC23="","",ROUND(($AC23/$AC$10)*$AD$10,2))) -> 88 | AE23: =IF($AD23="","",ROUND($AD23*$AE$10,2)) -> 44 | AF23: 45 | AG23: =IF(ISERROR(IF($AF23="","",ROUND(($AF23/$AF$10)*$AG$10,2))),"",IF($AF23="","",ROUND(($AF23/$AF$10)*$AG$10,2))) -> 90 | AH23: =IF($AG23="","",ROUND($AG23*$AH$10,2)) -> 18 | AI23: =IF(ISERROR(IF($AF23="","",ROUND(SUM($R23,$AE23,$AH23),2))),"",IF($AF23="","",ROUND(SUM($R23,$AE23,$AH23),2))) -> 89.9 | AJ23: =IF(ISERROR(IF($AF23="","",VLOOKUP(AI23,TRANSMUTATION_TABLE,4,TRUE))),"",IF($AF23="","",VLOOKUP(AI23,TRANSMUTATION_TABLE,4,TRUE))) -> 93
A24: 13 | B24: ='INPUT DATA'!B24 -> Naval, Patrick S. | F24: 26 | G24: 50 | H24: 19 | P24: =IF(COUNT($F24:$O24)=0,"",SUM($F24:$O24)) -> 95 | Q24: =IF(ISERROR(IF($P24="","",ROUND(($P24/$P$10)*$Q$10,2))),"",IF($P24="","",ROUND(($P24/$P$10)*$Q$10,2))) -> 95 | R24: =IF($Q24="","",ROUND($Q24*$R$10,2)) -> 28.5 | S24: 20 | AC24: =IF(COUNT($S24:$AB24)=0,"",SUM($S24:$AB24)) -> 20 | AD24: =IF(ISERROR(IF($AC24="","",ROUND(($AC24/$AC$10)*$AD$10,2))),"",IF($AC24="","",ROUND(($AC24/$AC$10)*$AD$10,2))) -> 80 | AE24: =IF($AD24="","",ROUND($AD24*$AE$10,2)) -> 40 | AF24: 49 | AG24: =IF(ISERROR(IF($AF24="","",ROUND(($AF24/$AF$10)*$AG$10,2))),"",IF($AF24="","",ROUND(($AF24/$AF$10)*$AG$10,2))) -> 98 | AH24: =IF($AG24="","",ROUND($AG24*$AH$10,2)) -> 19.6 | AI24: =IF(ISERROR(IF($AF24="","",ROUND(SUM($R24,$AE24,$AH24),2))),"",IF($AF24="","",ROUND(SUM($R24,$AE24,$AH24),2))) -> 88.1 | AJ24: =IF(ISERROR(IF($AF24="","",VLOOKUP(AI24,TRANSMUTATION_TABLE,4,TRUE))),"",IF($AF24="","",VLOOKUP(AI24,TRANSMUTATION_TABLE,4,TRUE))) -> 92
A25: 14 | B25: ='INPUT DATA'!B25 -> Ocampo, Gabriel C. | F25: 30 | G25: 40 | H25: 15 | P25: =IF(COUNT($F25:$O25)=0,"",SUM($F25:$O25)) -> 85 | Q25: =IF(ISERROR(IF($P25="","",ROUND(($P25/$P$10)*$Q$10,2))),"",IF($P25="","",ROUND(($P25/$P$10)*$Q$10,2))) -> 85 | R25: =IF($Q25="","",ROUND($Q25*$R$10,2)) -> 25.5 | S25: 25 | AC25: =IF(COUNT($S25:$AB25)=0,"",SUM($S25:$AB25)) -> 25 | AD25: =IF(ISERROR(IF($AC25="","",ROUND(($AC25/$AC$10)*$AD$10,2))),"",IF($AC25="","",ROUND(($AC25/$AC$10)*$AD$10,2))) -> 100 | AE25: =IF($AD25="","",ROUND($AD25*$AE$10,2)) -> 50 | AF25: 50 | AG25: =IF(ISERROR(IF($AF25="","",ROUND(($AF25/$AF$10)*$AG$10,2))),"",IF($AF25="","",ROUND(($AF25/$AF$10)*$AG$10,2))) -> 100 | AH25: =IF($AG25="","",ROUND($AG25*$AH$10,2)) -> 20 | AI25: =IF(ISERROR(IF($AF25="","",ROUND(SUM($R25,$AE25,$AH25),2))),"",IF($AF25="","",ROUND(SUM($R25,$AE25,$AH25),2))) -> 95.5 | AJ25: =IF(ISERROR(IF($AF25="","",VLOOKUP(AI25,TRANSMUTATION_TABLE,4,TRUE))),"",IF($AF25="","",VLOOKUP(AI25,TRANSMUTATION_TABLE,4,TRUE))) -> 97
A26: 15 | B26: ='INPUT DATA'!B26 -> Pascual, Cedric A. | F26: 27 | G26: 49 | H26: 20 | P26: =IF(COUNT($F26:$O26)=0,"",SUM($F26:$O26)) -> 96 | Q26: =IF(ISERROR(IF($P26="","",ROUND(($P26/$P$10)*$Q$10,2))),"",IF($P26="","",ROUND(($P26/$P$10)*$Q$10,2))) -> 96 | R26: =IF($Q26="","",ROUND($Q26*$R$10,2)) -> 28.8 | S26: 21 | AC26: =IF(COUNT($S26:$AB26)=0,"",SUM($S26:$AB26)) -> 21 | AD26: =IF(ISERROR(IF($AC26="","",ROUND(($AC26/$AC$10)*$AD$10,2))),"",IF($AC26="","",ROUND(($AC26/$AC$10)*$AD$10,2))) -> 84 | AE26: =IF($AD26="","",ROUND($AD26*$AE$10,2)) -> 42 | AF26: 45 | AG26: =IF(ISERROR(IF($AF26="","",ROUND(($AF26/$AF$10)*$AG$10,2))),"",IF($AF26="","",ROUND(($AF26/$AF$10)*$AG$10,2))) -> 90 | AH26: =IF($AG26="","",ROUND($AG26*$AH$10,2)) -> 18 | AI26: =IF(ISERROR(IF($AF26="","",ROUND(SUM($R26,$AE26,$AH26),2))),"",IF($AF26="","",ROUND(SUM($R26,$AE26,$AH26),2))) -> 88.8 | AJ26: =IF(ISERROR(IF($AF26="","",VLOOKUP(AI26,TRANSMUTATION_TABLE,4,TRUE))),"",IF($AF26="","",VLOOKUP(AI26,TRANSMUTATION_TABLE,4,TRUE))) -> 93
A27: 16 | B27: ='INPUT DATA'!B27 -> Quizon, Timothy E. | F27: 25 | G27: 50 | H27: 12 | P27: =IF(COUNT($F27:$O27)=0,"",SUM($F27:$O27)) -> 87 | Q27: =IF(ISERROR(IF($P27="","",ROUND(($P27/$P$10)*$Q$10,2))),"",IF($P27="","",ROUND(($P27/$P$10)*$Q$10,2))) -> 87 | R27: =IF($Q27="","",ROUND($Q27*$R$10,2)) -> 26.1 | S27: 24 | AC27: =IF(COUNT($S27:$AB27)=0,"",SUM($S27:$AB27)) -> 24 | AD27: =IF(ISERROR(IF($AC27="","",ROUND(($AC27/$AC$10)*$AD$10,2))),"",IF($AC27="","",ROUND(($AC27/$AC$10)*$AD$10,2))) -> 96 | AE27: =IF($AD27="","",ROUND($AD27*$AE$10,2)) -> 48 | AF27: 47 | AG27: =IF(ISERROR(IF($AF27="","",ROUND(($AF27/$AF$10)*$AG$10,2))),"",IF($AF27="","",ROUND(($AF27/$AF$10)*$AG$10,2))) -> 94 | AH27: =IF($AG27="","",ROUND($AG27*$AH$10,2)) -> 18.8 | AI27: =IF(ISERROR(IF($AF27="","",ROUND(SUM($R27,$AE27,$AH27),2))),"",IF($AF27="","",ROUND(SUM($R27,$AE27,$AH27),2))) -> 92.9 | AJ27: =IF(ISERROR(IF($AF27="","",VLOOKUP(AI27,TRANSMUTATION_TABLE,4,TRUE))),"",IF($AF27="","",VLOOKUP(AI27,TRANSMUTATION_TABLE,4,TRUE))) -> 95
A28: 17 | B28: ='INPUT DATA'!B28 -> Reyes, Dominic L. | F28: 29 | G28: 48 | H28: 15 | P28: =IF(COUNT($F28:$O28)=0,"",SUM($F28:$O28)) -> 92 | Q28: =IF(ISERROR(IF($P28="","",ROUND(($P28/$P$10)*$Q$10,2))),"",IF($P28="","",ROUND(($P28/$P$10)*$Q$10,2))) -> 92 | R28: =IF($Q28="","",ROUND($Q28*$R$10,2)) -> 27.6 | S28: 21 | AC28: =IF(COUNT($S28:$AB28)=0,"",SUM($S28:$AB28)) -> 21 | AD28: =IF(ISERROR(IF($AC28="","",ROUND(($AC28/$AC$10)*$AD$10,2))),"",IF($AC28="","",ROUND(($AC28/$AC$10)*$AD$10,2))) -> 84 | AE28: =IF($AD28="","",ROUND($AD28*$AE$10,2)) -> 42 | AF28: 49 | AG28: =IF(ISERROR(IF($AF28="","",ROUND(($AF28/$AF$10)*$AG$10,2))),"",IF($AF28="","",ROUND(($AF28/$AF$10)*$AG$10,2))) -> 98 | AH28: =IF($AG28="","",ROUND($AG28*$AH$10,2)) -> 19.6 | AI28: =IF(ISERROR(IF($AF28="","",ROUND(SUM($R28,$AE28,$AH28),2))),"",IF($AF28="","",ROUND(SUM($R28,$AE28,$AH28),2))) -> 89.2 | AJ28: =IF(ISERROR(IF($AF28="","",VLOOKUP(AI28,TRANSMUTATION_TABLE,4,TRUE))),"",IF($AF28="","",VLOOKUP(AI28,TRANSMUTATION_TABLE,4,TRUE))) -> 93
A29: 18 | B29: ='INPUT DATA'!B29 -> Santos, Elijah J. | F29: 27 | G29: 45 | H29: 19 | P29: =IF(COUNT($F29:$O29)=0,"",SUM($F29:$O29)) -> 91 | Q29: =IF(ISERROR(IF($P29="","",ROUND(($P29/$P$10)*$Q$10,2))),"",IF($P29="","",ROUND(($P29/$P$10)*$Q$10,2))) -> 91 | R29: =IF($Q29="","",ROUND($Q29*$R$10,2)) -> 27.3 | S29: 22 | AC29: =IF(COUNT($S29:$AB29)=0,"",SUM($S29:$AB29)) -> 22 | AD29: =IF(ISERROR(IF($AC29="","",ROUND(($AC29/$AC$10)*$AD$10,2))),"",IF($AC29="","",ROUND(($AC29/$AC$10)*$AD$10,2))) -> 88 | AE29: =IF($AD29="","",ROUND($AD29*$AE$10,2)) -> 44 | AF29: 45 | AG29: =IF(ISERROR(IF($AF29="","",ROUND(($AF29/$AF$10)*$AG$10,2))),"",IF($AF29="","",ROUND(($AF29/$AF$10)*$AG$10,2))) -> 90 | AH29: =IF($AG29="","",ROUND($AG29*$AH$10,2)) -> 18 | AI29: =IF(ISERROR(IF($AF29="","",ROUND(SUM($R29,$AE29,$AH29),2))),"",IF($AF29="","",ROUND(SUM($R29,$AE29,$AH29),2))) -> 89.3 | AJ29: =IF(ISERROR(IF($AF29="","",VLOOKUP(AI29,TRANSMUTATION_TABLE,4,TRUE))),"",IF($AF29="","",VLOOKUP(AI29,TRANSMUTATION_TABLE,4,TRUE))) -> 93
A30: 19 | B30: ='INPUT DATA'!B30 -> Torres, Benedict M. | F30: 26 | G30: 40 | H30: 18 | P30: =IF(COUNT($F30:$O30)=0,"",SUM($F30:$O30)) -> 84 | Q30: =IF(ISERROR(IF($P30="","",ROUND(($P30/$P$10)*$Q$10,2))),"",IF($P30="","",ROUND(($P30/$P$10)*$Q$10,2))) -> 84 | R30: =IF($Q30="","",ROUND($Q30*$R$10,2)) -> 25.2 | S30: 20 | AC30: =IF(COUNT($S30:$AB30)=0,"",SUM($S30:$AB30)) -> 20 | AD30: =IF(ISERROR(IF($AC30="","",ROUND(($AC30/$AC$10)*$AD$10,2))),"",IF($AC30="","",ROUND(($AC30/$AC$10)*$AD$10,2))) -> 80 | AE30: =IF($AD30="","",ROUND($AD30*$AE$10,2)) -> 40 | AF30: 47 | AG30: =IF(ISERROR(IF($AF30="","",ROUND(($AF30/$AF$10)*$AG$10,2))),"",IF($AF30="","",ROUND(($AF30/$AF$10)*$AG$10,2))) -> 94 | AH30: =IF($AG30="","",ROUND($AG30*$AH$10,2)) -> 18.8 | AI30: =IF(ISERROR(IF($AF30="","",ROUND(SUM($R30,$AE30,$AH30),2))),"",IF($AF30="","",ROUND(SUM($R30,$AE30,$AH30),2))) -> 84 | AJ30: =IF(ISERROR(IF($AF30="","",VLOOKUP(AI30,TRANSMUTATION_TABLE,4,TRUE))),"",IF($AF30="","",VLOOKUP(AI30,TRANSMUTATION_TABLE,4,TRUE))) -> 90
A31: 20 | B31: ='INPUT DATA'!B31 -> Umali, Vincent P. | F31: 30 | G31: 49 | H31: 18 | P31: =IF(COUNT($F31:$O31)=0,"",SUM($F31:$O31)) -> 97 | Q31: =IF(ISERROR(IF($P31="","",ROUND(($P31/$P$10)*$Q$10,2))),"",IF($P31="","",ROUND(($P31/$P$10)*$Q$10,2))) -> 97 | R31: =IF($Q31="","",ROUND($Q31*$R$10,2)) -> 29.1 | S31: 23 | AC31: =IF(COUNT($S31:$AB31)=0,"",SUM($S31:$AB31)) -> 23 | AD31: =IF(ISERROR(IF($AC31="","",ROUND(($AC31/$AC$10)*$AD$10,2))),"",IF($AC31="","",ROUND(($AC31/$AC$10)*$AD$10,2))) -> 92 | AE31: =IF($AD31="","",ROUND($AD31*$AE$10,2)) -> 46 | AF31: 45 | AG31: =IF(ISERROR(IF($AF31="","",ROUND(($AF31/$AF$10)*$AG$10,2))),"",IF($AF31="","",ROUND(($AF31/$AF$10)*$AG$10,2))) -> 90 | AH31: =IF($AG31="","",ROUND($AG31*$AH$10,2)) -> 18 | AI31: =IF(ISERROR(IF($AF31="","",ROUND(SUM($R31,$AE31,$AH31),2))),"",IF($AF31="","",ROUND(SUM($R31,$AE31,$AH31),2))) -> 93.1 | AJ31: =IF(ISERROR(IF($AF31="","",VLOOKUP(AI31,TRANSMUTATION_TABLE,4,TRUE))),"",IF($AF31="","",VLOOKUP(AI31,TRANSMUTATION_TABLE,4,TRUE))) -> 95
A32: 21 | B32: ='INPUT DATA'!B32 -> Valdez, Christian R. | F32: 25 | G32: 48 | H32: 19 | P32: =IF(COUNT($F32:$O32)=0,"",SUM($F32:$O32)) -> 92 | Q32: =IF(ISERROR(IF($P32="","",ROUND(($P32/$P$10)*$Q$10,2))),"",IF($P32="","",ROUND(($P32/$P$10)*$Q$10,2))) -> 92 | R32: =IF($Q32="","",ROUND($Q32*$R$10,2)) -> 27.6 | S32: 25 | AC32: =IF(COUNT($S32:$AB32)=0,"",SUM($S32:$AB32)) -> 25 | AD32: =IF(ISERROR(IF($AC32="","",ROUND(($AC32/$AC$10)*$AD$10,2))),"",IF($AC32="","",ROUND(($AC32/$AC$10)*$AD$10,2))) -> 100 | AE32: =IF($AD32="","",ROUND($AD32*$AE$10,2)) -> 50 | AF32: 49 | AG32: =IF(ISERROR(IF($AF32="","",ROUND(($AF32/$AF$10)*$AG$10,2))),"",IF($AF32="","",ROUND(($AF32/$AF$10)*$AG$10,2))) -> 98 | AH32: =IF($AG32="","",ROUND($AG32*$AH$10,2)) -> 19.6 | AI32: =IF(ISERROR(IF($AF32="","",ROUND(SUM($R32,$AE32,$AH32),2))),"",IF($AF32="","",ROUND(SUM($R32,$AE32,$AH32),2))) -> 97.2 | AJ32: =IF(ISERROR(IF($AF32="","",VLOOKUP(AI32,TRANSMUTATION_TABLE,4,TRUE))),"",IF($AF32="","",VLOOKUP(AI32,TRANSMUTATION_TABLE,4,TRUE))) -> 98
A33: 22 | B33: ='INPUT DATA'!B33 -> Yabut, Francis K. | F33: 29 | G33: 50 | H33: 20 | P33: =IF(COUNT($F33:$O33)=0,"",SUM($F33:$O33)) -> 99 | Q33: =IF(ISERROR(IF($P33="","",ROUND(($P33/$P$10)*$Q$10,2))),"",IF($P33="","",ROUND(($P33/$P$10)*$Q$10,2))) -> 99 | R33: =IF($Q33="","",ROUND($Q33*$R$10,2)) -> 29.7 | S33: 24 | AC33: =IF(COUNT($S33:$AB33)=0,"",SUM($S33:$AB33)) -> 24 | AD33: =IF(ISERROR(IF($AC33="","",ROUND(($AC33/$AC$10)*$AD$10,2))),"",IF($AC33="","",ROUND(($AC33/$AC$10)*$AD$10,2))) -> 96 | AE33: =IF($AD33="","",ROUND($AD33*$AE$10,2)) -> 48 | AF33: 47 | AG33: =IF(ISERROR(IF($AF33="","",ROUND(($AF33/$AF$10)*$AG$10,2))),"",IF($AF33="","",ROUND(($AF33/$AF$10)*$AG$10,2))) -> 94 | AH33: =IF($AG33="","",ROUND($AG33*$AH$10,2)) -> 18.8 | AI33: =IF(ISERROR(IF($AF33="","",ROUND(SUM($R33,$AE33,$AH33),2))),"",IF($AF33="","",ROUND(SUM($R33,$AE33,$AH33),2))) -> 96.5 | AJ33: =IF(ISERROR(IF($AF33="","",VLOOKUP(AI33,TRANSMUTATION_TABLE,4,TRUE))),"",IF($AF33="","",VLOOKUP(AI33,TRANSMUTATION_TABLE,4,TRUE))) -> 97
A34: 23 | B34: ='INPUT DATA'!B34 -> 0 | P34: =IF(COUNT($F34:$O34)=0,"",SUM($F34:$O34)) | Q34: =IF(ISERROR(IF($P34="","",ROUND(($P34/$P$10)*$Q$10,2))),"",IF($P34="","",ROUND(($P34/$P$10)*$Q$10,2))) | R34: =IF($Q34="","",ROUND($Q34*$R$10,2)) | AC34: =IF(COUNT($S34:$AB34)=0,"",SUM($S34:$AB34)) | AD34: =IF(ISERROR(IF($AC34="","",ROUND(($AC34/$AC$10)*$AD$10,2))),"",IF($AC34="","",ROUND(($AC34/$AC$10)*$AD$10,2))) | AE34: =IF($AD34="","",ROUND($AD34*$AE$10,2)) | AG34: =IF(ISERROR(IF($AF34="","",ROUND(($AF34/$AF$10)*$AG$10,2))),"",IF($AF34="","",ROUND(($AF34/$AF$10)*$AG$10,2))) | AH34: =IF($AG34="","",ROUND($AG34*$AH$10,2)) | AI34: =IF(ISERROR(IF($AF34="","",ROUND(SUM($R34,$AE34,$AH34),2))),"",IF($AF34="","",ROUND(SUM($R34,$AE34,$AH34),2))) | AJ34: =IF(ISERROR(IF($AF34="","",VLOOKUP(AI34,TRANSMUTATION_TABLE,4,TRUE))),"",IF($AF34="","",VLOOKUP(AI34,TRANSMUTATION_TABLE,4,TRUE)))
A35: 24 | B35: ='INPUT DATA'!B35 -> 0 | P35: =IF(COUNT($F35:$O35)=0,"",SUM($F35:$O35)) | Q35: =IF(ISERROR(IF($P35="","",ROUND(($P35/$P$10)*$Q$10,2))),"",IF($P35="","",ROUND(($P35/$P$10)*$Q$10,2))) | R35: =IF($Q35="","",ROUND($Q35*$R$10,2)) | AC35: =IF(COUNT($S35:$AB35)=0,"",SUM($S35:$AB35)) | AD35: =IF(ISERROR(IF($AC35="","",ROUND(($AC35/$AC$10)*$AD$10,2))),"",IF($AC35="","",ROUND(($AC35/$AC$10)*$AD$10,2))) | AE35: =IF($AD35="","",ROUND($AD35*$AE$10,2)) | AG35: =IF(ISERROR(IF($AF35="","",ROUND(($AF35/$AF$10)*$AG$10,2))),"",IF($AF35="","",ROUND(($AF35/$AF$10)*$AG$10,2))) | AH35: =IF($AG35="","",ROUND($AG35*$AH$10,2)) | AI35: =IF(ISERROR(IF($AF35="","",ROUND(SUM($R35,$AE35,$AH35),2))),"",IF($AF35="","",ROUND(SUM($R35,$AE35,$AH35),2))) | AJ35: =IF(ISERROR(IF($AF35="","",VLOOKUP(AI35,TRANSMUTATION_TABLE,4,TRUE))),"",IF($AF35="","",VLOOKUP(AI35,TRANSMUTATION_TABLE,4,TRUE)))
A36: 25 | B36: ='INPUT DATA'!B36 -> 0 | P36: =IF(COUNT($F36:$O36)=0,"",SUM($F36:$O36)) | Q36: =IF(ISERROR(IF($P36="","",ROUND(($P36/$P$10)*$Q$10,2))),"",IF($P36="","",ROUND(($P36/$P$10)*$Q$10,2))) | R36: =IF($Q36="","",ROUND($Q36*$R$10,2)) | AC36: =IF(COUNT($S36:$AB36)=0,"",SUM($S36:$AB36)) | AD36: =IF(ISERROR(IF($AC36="","",ROUND(($AC36/$AC$10)*$AD$10,2))),"",IF($AC36="","",ROUND(($AC36/$AC$10)*$AD$10,2))) | AE36: =IF($AD36="","",ROUND($AD36*$AE$10,2)) | AG36: =IF(ISERROR(IF($AF36="","",ROUND(($AF36/$AF$10)*$AG$10,2))),"",IF($AF36="","",ROUND(($AF36/$AF$10)*$AG$10,2))) | AH36: =IF($AG36="","",ROUND($AG36*$AH$10,2)) | AI36: =IF(ISERROR(IF($AF36="","",ROUND(SUM($R36,$AE36,$AH36),2))),"",IF($AF36="","",ROUND(SUM($R36,$AE36,$AH36),2))) | AJ36: =IF(ISERROR(IF($AF36="","",VLOOKUP(AI36,TRANSMUTATION_TABLE,4,TRUE))),"",IF($AF36="","",VLOOKUP(AI36,TRANSMUTATION_TABLE,4,TRUE)))
